Workbook

Sheet 사용법
B2: AI 파이프라인 통합 리소스/스케줄 관리시트 v11
B3: 한 소재 = 3줄 고정(기획/이미지/영상). 소재명·전달일은 첫줄만 입력하고 아래 2줄은 자동 상속됩니다.
B5: 1. 입력 규칙 - 어디에 뭘 넣나
B6: 블록 첫줄(기획 줄) | C6: 게임 타이틀 · 소재명 · 고객사 전달일 · 영상수/사이즈베리/다국어베리 · 상태. 이 6가지는 첫줄에만 넣습니다.
B7: 모든 줄 | C7: 담당자 + 오른쪽 날짜 칸의 MD. 직군마다 담당자가 다르므로 줄마다 각자 입력합니다.
B8: 자동 상속(회색칸) | C8: 2·3줄의 게임타이틀/소재명/전달일은 첫줄을 그대로 따라옵니다. 수식이니 덮어쓰지 마세요.
B9: 직군 칸 | C9: 기획/이미지/영상이 미리 고정돼 있습니다. 안 쓰는 직군은 담당자·MD를 비워두면 집계에서 자동 제외됩니다.
B11: 2. MD 입력 - 날짜 칸에 실제 값 그대로
B12: 직접 입력 | C12: 그날 실제 투입 MD를 그 날짜 칸에 씁니다. 균등분산이 아닙니다. 예) 8/5 기획 0.5 / 8/5 이미지 0.4 / 8/6 영상 1.0 / 8/7 영상 1.0
B13: 자동 계산 | C13: 직군MD·시작일·완료일은 그 줄에 넣은 날짜에서 자동으로 나옵니다. 소재 총MD와 최종완료일은 3줄을 묶어 첫줄에 표시됩니다.
B14: 시간→MD | C14: 1h=0.13 / 2h=0.25 / 4h=0.5 / 8h=1.0 (근무 1일 = 1.0MD)
B16: 3. 고객사 전달일 - 이 시트의 기준선
B17: 전달일 여유 | C17: 전달일 - 소재 최종완료일. 음수면 전달일을 넘긴 겁니다.
B18: 신호 | C18: 🔴지연(여유 음수) / 🟡임박(0~1일) / 🟢여유(2일 이상). 소재 블록 첫줄에 뜹니다.
B19: 빨간 날짜 칸 | C19: 전달일보다 뒤인 날짜에 MD를 넣으면 그 칸이 빨갛게 변합니다. 전달일을 넘겨 작업 중이라는 뜻입니다.
B21: 4. 색으로 보는 신호
B22: 파랑(상단) | C22: 그 직군 정원(TO)의 80~100%가 찬 날
B23: 보라(상단) | C23: 정원 초과 - 배정 조율 필요
B24: 빨강(날짜칸) | C24: 같은 담당자가 같은 날 여러 소재 합쳐 1.0MD(8시간)를 넘김, 또는 전달일을 넘겨 작업 중
B25: 회색(세로줄) | C25: 주말 또는 대한민국 공휴일 - 워킹데이 아님
B26: 줄 배경색 | C26: 기획=주황 / 이미지=초록 / 영상=파랑 계열로 직군을 구분합니다.
B28: 5. 용량과 구조
B29: 팀별 구간 | C29: 마케팅1~4팀 + 기타. 팀당 소재 20개(60행) 고정, 전체 월 100소재.
B30: 행이 모자라면 | C30: 그 팀 구간 안에서 3줄 단위로 삽입하고, 상단 합계와 연간요약의 참조 범위를 함께 넓혀야 합니다.
B31: 연간요약 | C31: 12개 월 탭에서 직접 집계합니다. 입력은 각 월 탭에서만 하세요.

Sheet 마스터
A1: 마스터 / 기준정보
A2: 게임 타이틀 | C2: 고객팀 | E2: 직군 | G2: 상태 | I2: 운영 파라미터 | J2: 값
A3: 뱀피르 | C3: 마케팅1팀 | E3: 기획 | G3: 대기 | I3: 연도 | J3: 2026
A4: RF 글로벌 | C4: 마케팅2팀 | E4: 이미지 | G4: 진행 | I4: 월 가동일수 | J4: 20
A5: SOL 인챈트 | C5: 마케팅3팀 | E5: 영상 | G5: 검수 | I5: 담당자 1일 캐파(MD) | J5: 1
A6: 스톤에이지펫월드 | C6: 마케팅4팀 | G6: 완료
A7: 칠대죄오리진 | C7: 기타 | I7: 직군 일 TO 정원 | J7: 명
A8: 세나리버스 | I8: 영상 | J8: 6
A9: 몬길 | I9: 이미지 | J9: 8
A10: 왕겜(GOT) | I10: 기획 | J10: 3
A11: 몬스터길들이기
A12: 라이즈오브 | I12: 대한민국 공휴일 (연도별 확인/수정 필요) | J12: 날짜
I13: 신정 | J13: =DATE($J$3,1,1)
I14: 설날연휴 | J14: =DATE($J$3,2,16)
I15: 설날 | J15: =DATE($J$3,2,17)
I16: 설날연휴 | J16: =DATE($J$3,2,18)
I17: 삼일절(대체) | J17: =DATE($J$3,3,2)
I18: 어린이날 | J18: =DATE($J$3,5,5)
I19: 부처님오신날(음력,확인필요) | J19: =DATE($J$3,5,24)
I20: 현충일 | J20: =DATE($J$3,6,6)
I21: 광복절 | J21: =DATE($J$3,8,15)
I22: 추석연휴(음력,확인필요) | J22: =DATE($J$3,9,24)
I23: 추석(음력,확인필요) | J23: =DATE($J$3,9,25)
I24: 추석연휴(음력,확인필요) | J24: =DATE($J$3,9,26)
I25: 개천절 | J25: =DATE($J$3,10,3)
I26: 한글날 | J26: =DATE($J$3,10,9)
I27: 성탄절 | J27: =DATE($J$3,12,25)
A30: 비나(VINA) 운영 시나리오 (참고)
A31: 방안 1 | C31: 기획+내부디자인+비나영상 - 비나 영상공수는 영상실 매출 귀속
A32: 방안 2 | C32: 비나=사이즈베리만 - 영상 베리는 디자인 흡수
A33: 방안 3 | C33: 비나 이미지TO 추가발주+추가비용
A34: 방안 4 | C34: 본사 프로세스 통합(이미지TO 추가X)

Sheet 연간요약
B2: 연간요약 - 월별 / 누적 / 가동률
B3: 각 월 탭에서 직접 집계합니다. 입력은 해당 월 탭에서만 하세요.
B5: 월 | C5: 영상MD | D5: 이미지MD | E5: 기획MD | F5: 합계MD | G5: 누적MD | H5: 영상수 | I5: 사이즈베리 | J5: 다국어베리 | K5: 소재수 | L5: 가동률
B6: 1월 | C6: =SUMIF('1월'!$E$9:$E$312,"영상",'1월'!$L$9:$L$312) | D6: =SUMIF('1월'!$E$9:$E$312,"이미지",'1월'!$L$9:$L$312) | E6: =SUMIF('1월'!$E$9:$E$312,"기획",'1월'!$L$9:$L$312) | F6: =SUM(C6:E6) | G6: =SUM($F$6:F6) | H6: =SUM('1월'!$O$9:$O$312) | I6: =SUM('1월'!$P$9:$P$312) | J6: =SUM('1월'!$Q$9:$Q$312) | K6: =COUNTIF('1월'!$A$9:$A$312,">0") | L6: =IFERROR(F6/(SUM('마스터'!$J$8:$J$10)*'마스터'!$J$4),0)
B7: 2월 | C7: =SUMIF('2월'!$E$9:$E$312,"영상",'2월'!$L$9:$L$312) | D7: =SUMIF('2월'!$E$9:$E$312,"이미지",'2월'!$L$9:$L$312) | E7: =SUMIF('2월'!$E$9:$E$312,"기획",'2월'!$L$9:$L$312) | F7: =SUM(C7:E7) | G7: =SUM($F$6:F7) | H7: =SUM('2월'!$O$9:$O$312) | I7: =SUM('2월'!$P$9:$P$312) | J7: =SUM('2월'!$Q$9:$Q$312) | K7: =COUNTIF('2월'!$A$9:$A$312,">0") | L7: =IFERROR(F7/(SUM('마스터'!$J$8:$J$10)*'마스터'!$J$4),0)
B8: 3월 | C8: =SUMIF('3월'!$E$9:$E$312,"영상",'3월'!$L$9:$L$312) | D8: =SUMIF('3월'!$E$9:$E$312,"이미지",'3월'!$L$9:$L$312) | E8: =SUMIF('3월'!$E$9:$E$312,"기획",'3월'!$L$9:$L$312) | F8: =SUM(C8:E8) | G8: =SUM($F$6:F8) | H8: =SUM('3월'!$O$9:$O$312) | I8: =SUM('3월'!$P$9:$P$312) | J8: =SUM('3월'!$Q$9:$Q$312) | K8: =COUNTIF('3월'!$A$9:$A$312,">0") | L8: =IFERROR(F8/(SUM('마스터'!$J$8:$J$10)*'마스터'!$J$4),0)
B9: 4월 | C9: =SUMIF('4월'!$E$9:$E$312,"영상",'4월'!$L$9:$L$312) | D9: =SUMIF('4월'!$E$9:$E$312,"이미지",'4월'!$L$9:$L$312) | E9: =SUMIF('4월'!$E$9:$E$312,"기획",'4월'!$L$9:$L$312) | F9: =SUM(C9:E9) | G9: =SUM($F$6:F9) | H9: =SUM('4월'!$O$9:$O$312) | I9: =SUM('4월'!$P$9:$P$312) | J9: =SUM('4월'!$Q$9:$Q$312) | K9: =COUNTIF('4월'!$A$9:$A$312,">0") | L9: =IFERROR(F9/(SUM('마스터'!$J$8:$J$10)*'마스터'!$J$4),0)
B10: 5월 | C10: =SUMIF('5월'!$E$9:$E$312,"영상",'5월'!$L$9:$L$312) | D10: =SUMIF('5월'!$E$9:$E$312,"이미지",'5월'!$L$9:$L$312) | E10: =SUMIF('5월'!$E$9:$E$312,"기획",'5월'!$L$9:$L$312) | F10: =SUM(C10:E10) | G10: =SUM($F$6:F10) | H10: =SUM('5월'!$O$9:$O$312) | I10: =SUM('5월'!$P$9:$P$312) | J10: =SUM('5월'!$Q$9:$Q$312) | K10: =COUNTIF('5월'!$A$9:$A$312,">0") | L10: =IFERROR(F10/(SUM('마스터'!$J$8:$J$10)*'마스터'!$J$4),0)
B11: 6월 | C11: =SUMIF('6월'!$E$9:$E$312,"영상",'6월'!$L$9:$L$312) | D11: =SUMIF('6월'!$E$9:$E$312,"이미지",'6월'!$L$9:$L$312) | E11: =SUMIF('6월'!$E$9:$E$312,"기획",'6월'!$L$9:$L$312) | F11: =SUM(C11:E11) | G11: =SUM($F$6:F11) | H11: =SUM('6월'!$O$9:$O$312) | I11: =SUM('6월'!$P$9:$P$312) | J11: =SUM('6월'!$Q$9:$Q$312) | K11: =COUNTIF('6월'!$A$9:$A$312,">0") | L11: =IFERROR(F11/(SUM('마스터'!$J$8:$J$10)*'마스터'!$J$4),0)
B12: 7월 | C12: =SUMIF('7월'!$E$9:$E$312,"영상",'7월'!$L$9:$L$312) | D12: =SUMIF('7월'!$E$9:$E$312,"이미지",'7월'!$L$9:$L$312) | E12: =SUMIF('7월'!$E$9:$E$312,"기획",'7월'!$L$9:$L$312) | F12: =SUM(C12:E12) | G12: =SUM($F$6:F12) | H12: =SUM('7월'!$O$9:$O$312) | I12: =SUM('7월'!$P$9:$P$312) | J12: =SUM('7월'!$Q$9:$Q$312) | K12: =COUNTIF('7월'!$A$9:$A$312,">0") | L12: =IFERROR(F12/(SUM('마스터'!$J$8:$J$10)*'마스터'!$J$4),0)
B13: 8월 | C13: =SUMIF('8월'!$E$9:$E$312,"영상",'8월'!$L$9:$L$312) | D13: =SUMIF('8월'!$E$9:$E$312,"이미지",'8월'!$L$9:$L$312) | E13: =SUMIF('8월'!$E$9:$E$312,"기획",'8월'!$L$9:$L$312) | F13: =SUM(C13:E13) | G13: =SUM($F$6:F13) | H13: =SUM('8월'!$O$9:$O$312) | I13: =SUM('8월'!$P$9:$P$312) | J13: =SUM('8월'!$Q$9:$Q$312) | K13: =COUNTIF('8월'!$A$9:$A$312,">0") | L13: =IFERROR(F13/(SUM('마스터'!$J$8:$J$10)*'마스터'!$J$4),0)
B14: 9월 | C14: =SUMIF('9월'!$E$9:$E$312,"영상",'9월'!$L$9:$L$312) | D14: =SUMIF('9월'!$E$9:$E$312,"이미지",'9월'!$L$9:$L$312) | E14: =SUMIF('9월'!$E$9:$E$312,"기획",'9월'!$L$9:$L$312) | F14: =SUM(C14:E14) | G14: =SUM($F$6:F14) | H14: =SUM('9월'!$O$9:$O$312) | I14: =SUM('9월'!$P$9:$P$312) | J14: =SUM('9월'!$Q$9:$Q$312) | K14: =COUNTIF('9월'!$A$9:$A$312,">0") | L14: =IFERROR(F14/(SUM('마스터'!$J$8:$J$10)*'마스터'!$J$4),0)
B15: 10월 | C15: =SUMIF('10월'!$E$9:$E$312,"영상",'10월'!$L$9:$L$312) | D15: =SUMIF('10월'!$E$9:$E$312,"이미지",'10월'!$L$9:$L$312) | E15: =SUMIF('10월'!$E$9:$E$312,"기획",'10월'!$L$9:$L$312) | F15: =SUM(C15:E15) | G15: =SUM($F$6:F15) | H15: =SUM('10월'!$O$9:$O$312) | I15: =SUM('10월'!$P$9:$P$312) | J15: =SUM('10월'!$Q$9:$Q$312) | K15: =COUNTIF('10월'!$A$9:$A$312,">0") | L15: =IFERROR(F15/(SUM('마스터'!$J$8:$J$10)*'마스터'!$J$4),0)
B16: 11월 | C16: =SUMIF('11월'!$E$9:$E$312,"영상",'11월'!$L$9:$L$312) | D16: =SUMIF('11월'!$E$9:$E$312,"이미지",'11월'!$L$9:$L$312) | E16: =SUMIF('11월'!$E$9:$E$312,"기획",'11월'!$L$9:$L$312) | F16: =SUM(C16:E16) | G16: =SUM($F$6:F16) | H16: =SUM('11월'!$O$9:$O$312) | I16: =SUM('11월'!$P$9:$P$312) | J16: =SUM('11월'!$Q$9:$Q$312) | K16: =COUNTIF('11월'!$A$9:$A$312,">0") | L16: =IFERROR(F16/(SUM('마스터'!$J$8:$J$10)*'마스터'!$J$4),0)
B17: 12월 | C17: =SUMIF('12월'!$E$9:$E$312,"영상",'12월'!$L$9:$L$312) | D17: =SUMIF('12월'!$E$9:$E$312,"이미지",'12월'!$L$9:$L$312) | E17: =SUMIF('12월'!$E$9:$E$312,"기획",'12월'!$L$9:$L$312) | F17: =SUM(C17:E17) | G17: =SUM($F$6:F17) | H17: =SUM('12월'!$O$9:$O$312) | I17: =SUM('12월'!$P$9:$P$312) | J17: =SUM('12월'!$Q$9:$Q$312) | K17: =COUNTIF('12월'!$A$9:$A$312,">0") | L17: =IFERROR(F17/(SUM('마스터'!$J$8:$J$10)*'마스터'!$J$4),0)
B18: 연간 합계 | C18: =SUM(C6:C17) | D18: =SUM(D6:D17) | E18: =SUM(E6:E17) | F18: =SUM(F6:F17) | G18: =F18 | H18: =SUM(H6:H17) | I18: =SUM(I6:I17) | J18: =SUM(J6:J17) | K18: =SUM(K6:K17) | L18: =IFERROR(F18/(SUM('마스터'!$J$8:$J$10)*'마스터'!$J$4*12),0)
B20: 상반기(1~6월) | C20: =SUM(C6:C11) | D20: =SUM(D6:D11) | E20: =SUM(E6:E11) | F20: =SUM(F6:F11) | H20: =SUM(H6:H11) | I20: =SUM(I6:I11) | J20: =SUM(J6:J11) | K20: =SUM(K6:K11)
B21: 하반기(7~12월) | C21: =SUM(C12:C17) | D21: =SUM(D12:D17) | E21: =SUM(E12:E17) | F21: =SUM(F12:F17) | H21: =SUM(H12:H17) | I21: =SUM(I12:I17) | J21: =SUM(J12:J17) | K21: =SUM(K12:K17)

Sheet 1월
A1: 1월 소재 정보 (소재 1개 = 기획/이미지/영상 3줄) | G1: 고객사 전달일 기준 (자동) | L1: 직군별 집계 (자동) | O1: 수량 (소재당 1번) | R1: 관리 | U1: 1월 간트 - 날짜 칸에 실제 MD 직접 입력 | 상단 4줄 = 일자별 직군 TO 상태
A2: No | B2: 게임 타이틀 | C2: 고객팀 | D2: 소재명(업무명) | E2: 직군 | F2: 담당자 | G2: 고객사 전달일 | H2: 신호 | I2: 전달일 여유 | J2: 소재 총MD | K2: 소재 최종완료 | L2: 직군 MD | M2: 직군 시작일 | N2: 직군 완료일 | O2: 영상 수 | P2: 사이즈 베리 | Q2: 다국어 베리 | R2: 상태 | S2: 비고 | U2: =IF(MONTH(DATE('마스터'!$J$3,1,1)+0)=1,DATE('마스터'!$J$3,1,1)+0,"") | V2: =IF(MONTH(DATE('마스터'!$J$3,1,1)+1)=1,DATE('마스터'!$J$3,1,1)+1,"") | W2: =IF(MONTH(DATE('마스터'!$J$3,1,1)+2)=1,DATE('마스터'!$J$3,1,1)+2,"") | X2: =IF(MONTH(DATE('마스터'!$J$3,1,1)+3)=1,DATE('마스터'!$J$3,1,1)+3,"") | Y2: =IF(MONTH(DATE('마스터'!$J$3,1,1)+4)=1,DATE('마스터'!$J$3,1,1)+4,"") | Z2: =IF(MONTH(DATE('마스터'!$J$3,1,1)+5)=1,DATE('마스터'!$J$3,1,1)+5,"") | AA2: =IF(MONTH(DATE('마스터'!$J$3,1,1)+6)=1,DATE('마스터'!$J$3,1,1)+6,"") | AB2: =IF(MONTH(DATE('마스터'!$J$3,1,1)+7)=1,DATE('마스터'!$J$3,1,1)+7,"") | AC2: =IF(MONTH(DATE('마스터'!$J$3,1,1)+8)=1,DATE('마스터'!$J$3,1,1)+8,"") | AD2: =IF(MONTH(DATE('마스터'!$J$3,1,1)+9)=1,DATE('마스터'!$J$3,1,1)+9,"") | AE2: =IF(MONTH(DATE('마스터'!$J$3,1,1)+10)=1,DATE('마스터'!$J$3,1,1)+10,"") | AF2: =IF(MONTH(DATE('마스터'!$J$3,1,1)+11)=1,DATE('마스터'!$J$3,1,1)+11,"") | AG2: =IF(MONTH(DATE('마스터'!$J$3,1,1)+12)=1,DATE('마스터'!$J$3,1,1)+12,"") | AH2: =IF(MONTH(DATE('마스터'!$J$3,1,1)+13)=1,DATE('마스터'!$J$3,1,1)+13,"") | AI2: =IF(MONTH(DATE('마스터'!$J$3,1,1)+14)=1,DATE('마스터'!$J$3,1,1)+14,"") | AJ2: =IF(MONTH(DATE('마스터'!$J$3,1,1)+15)=1,DATE('마스터'!$J$3,1,1)+15,"") | AK2: =IF(MONTH(DATE('마스터'!$J$3,1,1)+16)=1,DATE('마스터'!$J$3,1,1)+16,"") | AL2: =IF(MONTH(DATE('마스터'!$J$3,1,1)+17)=1,DATE('마스터'!$J$3,1,1)+17,"") | AM2: =IF(MONTH(DATE('마스터'!$J$3,1,1)+18)=1,DATE('마스터'!$J$3,1,1)+18,"") | AN2: =IF(MONTH(DATE('마스터'!$J$3,1,1)+19)=1,DATE('마스터'!$J$3,1,1)+19,"") | AO2: =IF(MONTH(DATE('마스터'!$J$3,1,1)+20)=1,DATE('마스터'!$J$3,1,1)+20,"") | AP2: =IF(MONTH(DATE('마스터'!$J$3,1,1)+21)=1,DATE('마스터'!$J$3,1,1)+21,"") | AQ2: =IF(MONTH(DATE('마스터'!$J$3,1,1)+22)=1,DATE('마스터'!$J$3,1,1)+22,"") | AR2: =IF(MONTH(DATE('마스터'!$J$3,1,1)+23)=1,DATE('마스터'!$J$3,1,1)+23,"") | AS2: =IF(MONTH(DATE('마스터'!$J$3,1,1)+24)=1,DATE('마스터'!$J$3,1,1)+24,"") | AT2: =IF(MONTH(DATE('마스터'!$J$3,1,1)+25)=1,DATE('마스터'!$J$3,1,1)+25,"") | AU2: =IF(MONTH(DATE('마스터'!$J$3,1,1)+26)=1,DATE('마스터'!$J$3,1,1)+26,"") | AV2: =IF(MONTH(DATE('마스터'!$J$3,1,1)+27)=1,DATE('마스터'!$J$3,1,1)+27,"") | AW2: =IF(MONTH(DATE('마스터'!$J$3,1,1)+28)=1,DATE('마스터'!$J$3,1,1)+28,"") | AX2: =IF(MONTH(DATE('마스터'!$J$3,1,1)+29)=1,DATE('마스터'!$J$3,1,1)+29,"") | AY2: =IF(MONTH(DATE('마스터'!$J$3,1,1)+30)=1,DATE('마스터'!$J$3,1,1)+30,"")
A3: 전체 TO (일자별 부하) | G3: 정원 | H3: =SUM('마스터'!$J$8:$J$10) | U3: =SUM(U$9:U$312) | V3: =SUM(V$9:V$312) | W3: =SUM(W$9:W$312) | X3: =SUM(X$9:X$312) | Y3: =SUM(Y$9:Y$312) | Z3: =SUM(Z$9:Z$312) | AA3: =SUM(AA$9:AA$312) | AB3: =SUM(AB$9:AB$312) | ... AY3: =SUM(AY$9:AY$312)
A4: 영상 TO | G4: 정원 | H4: ='마스터'!$J$8 | U4: =SUMIF($E$9:$E$312,"영상",U$9:U$312) | V4: =SUMIF($E$9:$E$312,"영상",V$9:V$312) | W4: =SUMIF($E$9:$E$312,"영상",W$9:W$312) | X4: =SUMIF($E$9:$E$312,"영상",X$9:X$312) | Y4: =SUMIF($E$9:$E$312,"영상",Y$9:Y$312) | Z4: =SUMIF($E$9:$E$312,"영상",Z$9:Z$312) | AA4: =SUMIF($E$9:$E$312,"영상",AA$9:AA$312) | AB4: =SUMIF($E$9:$E$312,"영상",AB$9:AB$312) | ... AY4: =SUMIF($E$9:$E$312,"영상",AY$9:AY$312)
A5: 이미지 TO | G5: 정원 | H5: ='마스터'!$J$9 | U5: =SUMIF($E$9:$E$312,"이미지",U$9:U$312) | V5: =SUMIF($E$9:$E$312,"이미지",V$9:V$312) | W5: =SUMIF($E$9:$E$312,"이미지",W$9:W$312) | X5: =SUMIF($E$9:$E$312,"이미지",X$9:X$312) | Y5: =SUMIF($E$9:$E$312,"이미지",Y$9:Y$312) | Z5: =SUMIF($E$9:$E$312,"이미지",Z$9:Z$312) | AA5: =SUMIF($E$9:$E$312,"이미지",AA$9:AA$312) | AB5: =SUMIF($E$9:$E$312,"이미지",AB$9:AB$312) | ... AY5: =SUMIF($E$9:$E$312,"이미지",AY$9:AY$312)
A6: 기획 TO | G6: 정원 | H6: ='마스터'!$J$10 | U6: =SUMIF($E$9:$E$312,"기획",U$9:U$312) | V6: =SUMIF($E$9:$E$312,"기획",V$9:V$312) | W6: =SUMIF($E$9:$E$312,"기획",W$9:W$312) | X6: =SUMIF($E$9:$E$312,"기획",X$9:X$312) | Y6: =SUMIF($E$9:$E$312,"기획",Y$9:Y$312) | Z6: =SUMIF($E$9:$E$312,"기획",Z$9:Z$312) | AA6: =SUMIF($E$9:$E$312,"기획",AA$9:AA$312) | AB6: =SUMIF($E$9:$E$312,"기획",AB$9:AB$312) | ... AY6: =SUMIF($E$9:$E$312,"기획",AY$9:AY$312)
A7: ▼ 아래부터 입력. 노란칸=직접 입력 / 회색칸=자동(건드리지 마세요)
A8: 마케팅1팀 (9~68행 · 소재 20개)
A9: =IF($D$9="","",1) | C9: 마케팅1팀 | E9: 기획 | H9: =IF($I$9="","",IF($I$9<0,"🔴지연",IF($I$9<=1,"🟡임박","🟢여유"))) | I9: =IF(OR($G$9="",$K$9=""),"",$G$9-$K$9) | J9: =IF(SUM($L$9:$L$11)=0,"",SUM($L$9:$L$11)) | K9: =IF($J$9="","",MAX($N$9:$N$11)) | L9: =IF(SUM(U9:AY9)=0,"",SUM(U9:AY9)) | M9: =IFERROR(INDEX(U$2:AY$2,MATCH(TRUE,INDEX(U9:AY9<>"",0),0)),"") | N9: =IFERROR(LOOKUP(2,1/(U9:AY9<>""),U$2:AY$2),"")
B10: =IF($B$9="","",$B$9) | C10: 마케팅1팀 | D10: =IF($D$9="","",$D$9) | E10: 이미지 | G10: =IF($G$9="","",$G$9) | L10: =IF(SUM(U10:AY10)=0,"",SUM(U10:AY10)) | M10: =IFERROR(INDEX(U$2:AY$2,MATCH(TRUE,INDEX(U10:AY10<>"",0),0)),"") | N10: =IFERROR(LOOKUP(2,1/(U10:AY10<>""),U$2:AY$2),"")
B11: =IF($B$9="","",$B$9) | C11: 마케팅1팀 | D11: =IF($D$9="","",$D$9) | E11: 영상 | G11: =IF($G$9="","",$G$9) | L11: =IF(SUM(U11:AY11)=0,"",SUM(U11:AY11)) | M11: =IFERROR(INDEX(U$2:AY$2,MATCH(TRUE,INDEX(U11:AY11<>"",0),0)),"") | N11: =IFERROR(LOOKUP(2,1/(U11:AY11<>""),U$2:AY$2),"")
A12: =IF($D$12="","",2) | C12: 마케팅1팀 | E12: 기획 | H12: =IF($I$12="","",IF($I$12<0,"🔴지연",IF($I$12<=1,"🟡임박","🟢여유"))) | I12: =IF(OR($G$12="",$K$12=""),"",$G$12-$K$12) | J12: =IF(SUM($L$12:$L$14)=0,"",SUM($L$12:$L$14)) | K12: =IF($J$12="","",MAX($N$12:$N$14)) | L12: =IF(SUM(U12:AY12)=0,"",SUM(U12:AY12)) | M12: =IFERROR(INDEX(U$2:AY$2,MATCH(TRUE,INDEX(U12:AY12<>"",0),0)),"") | N12: =IFERROR(LOOKUP(2,1/(U12:AY12<>""),U$2:AY$2),"")
B13: =IF($B$12="","",$B$12) | C13: 마케팅1팀 | D13: =IF($D$12="","",$D$12) | E13: 이미지 | G13: =IF($G$12="","",$G$12) | L13: =IF(SUM(U13:AY13)=0,"",SUM(U13:AY13)) | M13: =IFERROR(INDEX(U$2:AY$2,MATCH(TRUE,INDEX(U13:AY13<>"",0),0)),"") | N13: =IFERROR(LOOKUP(2,1/(U13:AY13<>""),U$2:AY$2),"")
B14: =IF($B$12="","",$B$12) | C14: 마케팅1팀 | D14: =IF($D$12="","",$D$12) | E14: 영상 | G14: =IF($G$12="","",$G$12) | L14: =IF(SUM(U14:AY14)=0,"",SUM(U14:AY14)) | M14: =IFERROR(INDEX(U$2:AY$2,MATCH(TRUE,INDEX(U14:AY14<>"",0),0)),"") | N14: =IFERROR(LOOKUP(2,1/(U14:AY14<>""),U$2:AY$2),"")
A15: =IF($D$15="","",3) | C15: 마케팅1팀 | E15: 기획 | H15: =IF($I$15="","",IF($I$15<0,"🔴지연",IF($I$15<=1,"🟡임박","🟢여유"))) | I15: =IF(OR($G$15="",$K$15=""),"",$G$15-$K$15) | J15: =IF(SUM($L$15:$L$17)=0,"",SUM($L$15:$L$17)) | K15: =IF($J$15="","",MAX($N$15:$N$17)) | L15: =IF(SUM(U15:AY15)=0,"",SUM(U15:AY15)) | M15: =IFERROR(INDEX(U$2:AY$2,MATCH(TRUE,INDEX(U15:AY15<>"",0),0)),"") | N15: =IFERROR(LOOKUP(2,1/(U15:AY15<>""),U$2:AY$2),"")
B16: =IF($B$15="","",$B$15) | C16: 마케팅1팀 | D16: =IF($D$15="","",$D$15) | E16: 이미지 | G16: =IF($G$15="","",$G$15) | L16: =IF(SUM(U16:AY16)=0,"",SUM(U16:AY16)) | M16: =IFERROR(INDEX(U$2:AY$2,MATCH(TRUE,INDEX(U16:AY16<>"",0),0)),"") | N16: =IFERROR(LOOKUP(2,1/(U16:AY16<>""),U$2:AY$2),"")
B17: =IF($B$15="","",$B$15) | C17: 마케팅1팀 | D17: =IF($D$15="","",$D$15) | E17: 영상 | G17: =IF($G$15="","",$G$15) | L17: =IF(SUM(U17:AY17)=0,"",SUM(U17:AY17)) | M17: =IFERROR(INDEX(U$2:AY$2,MATCH(TRUE,INDEX(U17:AY17<>"",0),0)),"") | N17: =IFERROR(LOOKUP(2,1/(U17:AY17<>""),U$2:AY$2),"")
A18: =IF($D$18="","",4) | C18: 마케팅1팀 | E18: 기획 | H18: =IF($I$18="","",IF($I$18<0,"🔴지연",IF($I$18<=1,"🟡임박","🟢여유"))) | I18: =IF(OR($G$18="",$K$18=""),"",$G$18-$K$18) | J18: =IF(SUM($L$18:$L$20)=0,"",SUM($L$18:$L$20)) | K18: =IF($J$18="","",MAX($N$18:$N$20)) | L18: =IF(SUM(U18:AY18)=0,"",SUM(U18:AY18)) | M18: =IFERROR(INDEX(U$2:AY$2,MATCH(TRUE,INDEX(U18:AY18<>"",0),0)),"") | N18: =IFERROR(LOOKUP(2,1/(U18:AY18<>""),U$2:AY$2),"")
B19: =IF($B$18="","",$B$18) | C19: 마케팅1팀 | D19: =IF($D$18="","",$D$18) | E19: 이미지 | G19: =IF($G$18="","",$G$18) | L19: =IF(SUM(U19:AY19)=0,"",SUM(U19:AY19)) | M19: =IFERROR(INDEX(U$2:AY$2,MATCH(TRUE,INDEX(U19:AY19<>"",0),0)),"") | N19: =IFERROR(LOOKUP(2,1/(U19:AY19<>""),U$2:AY$2),"")
B20: =IF($B$18="","",$B$18) | C20: 마케팅1팀 | D20: =IF($D$18="","",$D$18) | E20: 영상 | G20: =IF($G$18="","",$G$18) | L20: =IF(SUM(U20:AY20)=0,"",SUM(U20:AY20)) | M20: =IFERROR(INDEX(U$2:AY$2,MATCH(TRUE,INDEX(U20:AY20<>"",0),0)),"") | N20: =IFERROR(LOOKUP(2,1/(U20:AY20<>""),U$2:AY$2),"")
A21: =IF($D$21="","",5) | C21: 마케팅1팀 | E21: 기획 | H21: =IF($I$21="","",IF($I$21<0,"🔴지연",IF($I$21<=1,"🟡임박","🟢여유"))) | I21: =IF(OR($G$21="",$K$21=""),"",$G$21-$K$21) | J21: =IF(SUM($L$21:$L$23)=0,"",SUM($L$21:$L$23)) | K21: =IF($J$21="","",MAX($N$21:$N$23)) | L21: =IF(SUM(U21:AY21)=0,"",SUM(U21:AY21)) | M21: =IFERROR(INDEX(U$2:AY$2,MATCH(TRUE,INDEX(U21:AY21<>"",0),0)),"") | N21: =IFERROR(LOOKUP(2,1/(U21:AY21<>""),U$2:AY$2),"")
B22: =IF($B$21="","",$B$21) | C22: 마케팅1팀 | D22: =IF($D$21="","",$D$21) | E22: 이미지 | G22: =IF($G$21="","",$G$21) | L22: =IF(SUM(U22:AY22)=0,"",SUM(U22:AY22)) | M22: =IFERROR(INDEX(U$2:AY$2,MATCH(TRUE,INDEX(U22:AY22<>"",0),0)),"") | N22: =IFERROR(LOOKUP(2,1/(U22:AY22<>""),U$2:AY$2),"")
B23: =IF($B$21="","",$B$21) | C23: 마케팅1팀 | D23: =IF($D$21="","",$D$21) | E23: 영상 | G23: =IF($G$21="","",$G$21) | L23: =IF(SUM(U23:AY23)=0,"",SUM(U23:AY23)) | M23: =IFERROR(INDEX(U$2:AY$2,MATCH(TRUE,INDEX(U23:AY23<>"",0),0)),"") | N23: =IFERROR(LOOKUP(2,1/(U23:AY23<>""),U$2:AY$2),"")
A24: =IF($D$24="","",6) | C24: 마케팅1팀 | E24: 기획 | H24: =IF($I$24="","",IF($I$24<0,"🔴지연",IF($I$24<=1,"🟡임박","🟢여유"))) | I24: =IF(OR($G$24="",$K$24=""),"",$G$24-$K$24) | J24: =IF(SUM($L$24:$L$26)=0,"",SUM($L$24:$L$26)) | K24: =IF($J$24="","",MAX($N$24:$N$26)) | L24: =IF(SUM(U24:AY24)=0,"",SUM(U24:AY24)) | M24: =IFERROR(INDEX(U$2:AY$2,MATCH(TRUE,INDEX(U24:AY24<>"",0),0)),"") | N24: =IFERROR(LOOKUP(2,1/(U24:AY24<>""),U$2:AY$2),"")
B25: =IF($B$24="","",$B$24) | C25: 마케팅1팀 | D25: =IF($D$24="","",$D$24) | E25: 이미지 | G25: =IF($G$24="","",$G$24) | L25: =IF(SUM(U25:AY25)=0,"",SUM(U25:AY25)) | M25: =IFERROR(INDEX(U$2:AY$2,MATCH(TRUE,INDEX(U25:AY25<>"",0),0)),"") | N25: =IFERROR(LOOKUP(2,1/(U25:AY25<>""),U$2:AY$2),"")
B26: =IF($B$24="","",$B$24) | C26: 마케팅1팀 | D26: =IF($D$24="","",$D$24) | E26: 영상 | G26: =IF($G$24="","",$G$24) | L26: =IF(SUM(U26:AY26)=0,"",SUM(U26:AY26)) | M26: =IFERROR(INDEX(U$2:AY$2,MATCH(TRUE,INDEX(U26:AY26<>"",0),0)),"") | N26: =IFERROR(LOOKUP(2,1/(U26:AY26<>""),U$2:AY$2),"")
A27: =IF($D$27="","",7) | C27: 마케팅1팀 | E27: 기획 | H27: =IF($I$27="","",IF($I$27<0,"🔴지연",IF($I$27<=1,"🟡임박","🟢여유"))) | I27: =IF(OR($G$27="",$K$27=""),"",$G$27-$K$27) | J27: =IF(SUM($L$27:$L$29)=0,"",SUM($L$27:$L$29)) | K27: =IF($J$27="","",MAX($N$27:$N$29)) | L27: =IF(SUM(U27:AY27)=0,"",SUM(U27:AY27)) | M27: =IFERROR(INDEX(U$2:AY$2,MATCH(TRUE,INDEX(U27:AY27<>"",0),0)),"") | N27: =IFERROR(LOOKUP(2,1/(U27:AY27<>""),U$2:AY$2),"")
B28: =IF($B$27="","",$B$27) | C28: 마케팅1팀 | D28: =IF($D$27="","",$D$27) | E28: 이미지 | G28: =IF($G$27="","",$G$27) | L28: =IF(SUM(U28:AY28)=0,"",SUM(U28:AY28)) | M28: =IFERROR(INDEX(U$2:AY$2,MATCH(TRUE,INDEX(U28:AY28<>"",0),0)),"") | N28: =IFERROR(LOOKUP(2,1/(U28:AY28<>""),U$2:AY$2),"")
B29: =IF($B$27="","",$B$27) | C29: 마케팅1팀 | D29: =IF($D$27="","",$D$27) | E29: 영상 | G29: =IF($G$27="","",$G$27) | L29: =IF(SUM(U29:AY29)=0,"",SUM(U29:AY29)) | M29: =IFERROR(INDEX(U$2:AY$2,MATCH(TRUE,INDEX(U29:AY29<>"",0),0)),"") | N29: =IFERROR(LOOKUP(2,1/(U29:AY29<>""),U$2:AY$2),"")
A30: =IF($D$30="","",8) | C30: 마케팅1팀 | E30: 기획 | H30: =IF($I$30="","",IF($I$30<0,"🔴지연",IF($I$30<=1,"🟡임박","🟢여유"))) | I30: =IF(OR($G$30="",$K$30=""),"",$G$30-$K$30) | J30: =IF(SUM($L$30:$L$32)=0,"",SUM($L$30:$L$32)) | K30: =IF($J$30="","",MAX($N$30:$N$32)) | L30: =IF(SUM(U30:AY30)=0,"",SUM(U30:AY30)) | M30: =IFERROR(INDEX(U$2:AY$2,MATCH(TRUE,INDEX(U30:AY30<>"",0),0)),"") | N30: =IFERROR(LOOKUP(2,1/(U30:AY30<>""),U$2:AY$2),"")
B31: =IF($B$30="","",$B$30) | C31: 마케팅1팀 | D31: =IF($D$30="","",$D$30) | E31: 이미지 | G31: =IF($G$30="","",$G$30) | L31: =IF(SUM(U31:AY31)=0,"",SUM(U31:AY31)) | M31: =IFERROR(INDEX(U$2:AY$2,MATCH(TRUE,INDEX(U31:AY31<>"",0),0)),"") | N31: =IFERROR(LOOKUP(2,1/(U31:AY31<>""),U$2:AY$2),"")
B32: =IF($B$30="","",$B$30) | C32: 마케팅1팀 | D32: =IF($D$30="","",$D$30) | E32: 영상 | G32: =IF($G$30="","",$G$30) | L32: =IF(SUM(U32:AY32)=0,"",SUM(U32:AY32)) | M32: =IFERROR(INDEX(U$2:AY$2,MATCH(TRUE,INDEX(U32:AY32<>"",0),0)),"") | N32: =IFERROR(LOOKUP(2,1/(U32:AY32<>""),U$2:AY$2),"")
A33: =IF($D$33="","",9) | C33: 마케팅1팀 | E33: 기획 | H33: =IF($I$33="","",IF($I$33<0,"🔴지연",IF($I$33<=1,"🟡임박","🟢여유"))) | I33: =IF(OR($G$33="",$K$33=""),"",$G$33-$K$33) | J33: =IF(SUM($L$33:$L$35)=0,"",SUM($L$33:$L$35)) | K33: =IF($J$33="","",MAX($N$33:$N$35)) | L33: =IF(SUM(U33:AY33)=0,"",SUM(U33:AY33)) | M33: =IFERROR(INDEX(U$2:AY$2,MATCH(TRUE,INDEX(U33:AY33<>"",0),0)),"") | N33: =IFERROR(LOOKUP(2,1/(U33:AY33<>""),U$2:AY$2),"")
B34: =IF($B$33="","",$B$33) | C34: 마케팅1팀 | D34: =IF($D$33="","",$D$33) | E34: 이미지 | G34: =IF($G$33="","",$G$33) | L34: =IF(SUM(U34:AY34)=0,"",SUM(U34:AY34)) | M34: =IFERROR(INDEX(U$2:AY$2,MATCH(TRUE,INDEX(U34:AY34<>"",0),0)),"") | N34: =IFERROR(LOOKUP(2,1/(U34:AY34<>""),U$2:AY$2),"")
B35: =IF($B$33="","",$B$33) | C35: 마케팅1팀 | D35: =IF($D$33="","",$D$33) | E35: 영상 | G35: =IF($G$33="","",$G$33) | L35: =IF(SUM(U35:AY35)=0,"",SUM(U35:AY35)) | M35: =IFERROR(INDEX(U$2:AY$2,MATCH(TRUE,INDEX(U35:AY35<>"",0),0)),"") | N35: =IFERROR(LOOKUP(2,1/(U35:AY35<>""),U$2:AY$2),"")
A36: =IF($D$36="","",10) | C36: 마케팅1팀 | E36: 기획 | H36: =IF($I$36="","",IF($I$36<0,"🔴지연",IF($I$36<=1,"🟡임박","🟢여유"))) | I36: =IF(OR($G$36="",$K$36=""),"",$G$36-$K$36) | J36: =IF(SUM($L$36:$L$38)=0,"",SUM($L$36:$L$38)) | K36: =IF($J$36="","",MAX($N$36:$N$38)) | L36: =IF(SUM(U36:AY36)=0,"",SUM(U36:AY36)) | M36: =IFERROR(INDEX(U$2:AY$2,MATCH(TRUE,INDEX(U36:AY36<>"",0),0)),"") | N36: =IFERROR(LOOKUP(2,1/(U36:AY36<>""),U$2:AY$2),"")
B37: =IF($B$36="","",$B$36) | C37: 마케팅1팀 | D37: =IF($D$36="","",$D$36) | E37: 이미지 | G37: =IF($G$36="","",$G$36) | L37: =IF(SUM(U37:AY37)=0,"",SUM(U37:AY37)) | M37: =IFERROR(INDEX(U$2:AY$2,MATCH(TRUE,INDEX(U37:AY37<>"",0),0)),"") | N37: =IFERROR(LOOKUP(2,1/(U37:AY37<>""),U$2:AY$2),"")
B38: =IF($B$36="","",$B$36) | C38: 마케팅1팀 | D38: =IF($D$36="","",$D$36) | E38: 영상 | G38: =IF($G$36="","",$G$36) | L38: =IF(SUM(U38:AY38)=0,"",SUM(U38:AY38)) | M38: =IFERROR(INDEX(U$2:AY$2,MATCH(TRUE,INDEX(U38:AY38<>"",0),0)),"") | N38: =IFERROR(LOOKUP(2,1/(U38:AY38<>""),U$2:AY$2),"")
A39: =IF($D$39="","",11) | C39: 마케팅1팀 | E39: 기획 | H39: =IF($I$39="","",IF($I$39<0,"🔴지연",IF($I$39<=1,"🟡임박","🟢여유"))) | I39: =IF(OR($G$39="",$K$39=""),"",$G$39-$K$39) | J39: =IF(SUM($L$39:$L$41)=0,"",SUM($L$39:$L$41)) | K39: =IF($J$39="","",MAX($N$39:$N$41)) | L39: =IF(SUM(U39:AY39)=0,"",SUM(U39:AY39)) | M39: =IFERROR(INDEX(U$2:AY$2,MATCH(TRUE,INDEX(U39:AY39<>"",0),0)),"") | N39: =IFERROR(LOOKUP(2,1/(U39:AY39<>""),U$2:AY$2),"")
B40: =IF($B$39="","",$B$39) | C40: 마케팅1팀 | D40: =IF($D$39="","",$D$39) | E40: 이미지 | G40: =IF($G$39="","",$G$39) | L40: =IF(SUM(U40:AY40)=0,"",SUM(U40:AY40)) | M40: =IFERROR(INDEX(U$2:AY$2,MATCH(TRUE,INDEX(U40:AY40<>"",0),0)),"") | N40: =IFERROR(LOOKUP(2,1/(U40:AY40<>""),U$2:AY$2),"")
...

Sheet 2월
A1: 2월 소재 정보 (소재 1개 = 기획/이미지/영상 3줄) | G1: 고객사 전달일 기준 (자동) | L1: 직군별 집계 (자동) | O1: 수량 (소재당 1번) | R1: 관리 | U1: 2월 간트 - 날짜 칸에 실제 MD 직접 입력 | 상단 4줄 = 일자별 직군 TO 상태
A2: No | B2: 게임 타이틀 | C2: 고객팀 | D2: 소재명(업무명) | E2: 직군 | F2: 담당자 | G2: 고객사 전달일 | H2: 신호 | I2: 전달일 여유 | J2: 소재 총MD | K2: 소재 최종완료 | L2: 직군 MD | M2: 직군 시작일 | N2: 직군 완료일 | O2: 영상 수 | P2: 사이즈 베리 | Q2: 다국어 베리 | R2: 상태 | S2: 비고 | U2: =IF(MONTH(DATE('마스터'!$J$3,2,1)+0)=2,DATE('마스터'!$J$3,2,1)+0,"") | V2: =IF(MONTH(DATE('마스터'!$J$3,2,1)+1)=2,DATE('마스터'!$J$3,2,1)+1,"") | W2: =IF(MONTH(DATE('마스터'!$J$3,2,1)+2)=2,DATE('마스터'!$J$3,2,1)+2,"") | X2: =IF(MONTH(DATE('마스터'!$J$3,2,1)+3)=2,DATE('마스터'!$J$3,2,1)+3,"") | Y2: =IF(MONTH(DATE('마스터'!$J$3,2,1)+4)=2,DATE('마스터'!$J$3,2,1)+4,"") | Z2: =IF(MONTH(DATE('마스터'!$J$3,2,1)+5)=2,DATE('마스터'!$J$3,2,1)+5,"") | AA2: =IF(MONTH(DATE('마스터'!$J$3,2,1)+6)=2,DATE('마스터'!$J$3,2,1)+6,"") | AB2: =IF(MONTH(DATE('마스터'!$J$3,2,1)+7)=2,DATE('마스터'!$J$3,2,1)+7,"") | AC2: =IF(MONTH(DATE('마스터'!$J$3,2,1)+8)=2,DATE('마스터'!$J$3,2,1)+8,"") | AD2: =IF(MONTH(DATE('마스터'!$J$3,2,1)+9)=2,DATE('마스터'!$J$3,2,1)+9,"") | AE2: =IF(MONTH(DATE('마스터'!$J$3,2,1)+10)=2,DATE('마스터'!$J$3,2,1)+10,"") | AF2: =IF(MONTH(DATE('마스터'!$J$3,2,1)+11)=2,DATE('마스터'!$J$3,2,1)+11,"") | AG2: =IF(MONTH(DATE('마스터'!$J$3,2,1)+12)=2,DATE('마스터'!$J$3,2,1)+12,"") | AH2: =IF(MONTH(DATE('마스터'!$J$3,2,1)+13)=2,DATE('마스터'!$J$3,2,1)+13,"") | AI2: =IF(MONTH(DATE('마스터'!$J$3,2,1)+14)=2,DATE('마스터'!$J$3,2,1)+14,"") | AJ2: =IF(MONTH(DATE('마스터'!$J$3,2,1)+15)=2,DATE('마스터'!$J$3,2,1)+15,"") | AK2: =IF(MONTH(DATE('마스터'!$J$3,2,1)+16)=2,DATE('마스터'!$J$3,2,1)+16,"") | AL2: =IF(MONTH(DATE('마스터'!$J$3,2,1)+17)=2,DATE('마스터'!$J$3,2,1)+17,"") | AM2: =IF(MONTH(DATE('마스터'!$J$3,2,1)+18)=2,DATE('마스터'!$J$3,2,1)+18,"") | AN2: =IF(MONTH(DATE('마스터'!$J$3,2,1)+19)=2,DATE('마스터'!$J$3,2,1)+19,"") | AO2: =IF(MONTH(DATE('마스터'!$J$3,2,1)+20)=2,DATE('마스터'!$J$3,2,1)+20,"") | AP2: =IF(MONTH(DATE('마스터'!$J$3,2,1)+21)=2,DATE('마스터'!$J$3,2,1)+21,"") | AQ2: =IF(MONTH(DATE('마스터'!$J$3,2,1)+22)=2,DATE('마스터'!$J$3,2,1)+22,"") | AR2: =IF(MONTH(DATE('마스터'!$J$3,2,1)+23)=2,DATE('마스터'!$J$3,2,1)+23,"") | AS2: =IF(MONTH(DATE('마스터'!$J$3,2,1)+24)=2,DATE('마스터'!$J$3,2,1)+24,"") | AT2: =IF(MONTH(DATE('마스터'!$J$3,2,1)+25)=2,DATE('마스터'!$J$3,2,1)+25,"") | AU2: =IF(MONTH(DATE('마스터'!$J$3,2,1)+26)=2,DATE('마스터'!$J$3,2,1)+26,"") | AV2: =IF(MONTH(DATE('마스터'!$J$3,2,1)+27)=2,DATE('마스터'!$J$3,2,1)+27,"") | AW2: =IF(MONTH(DATE('마스터'!$J$3,2,1)+28)=2,DATE('마스터'!$J$3,2,1)+28,"") | AX2: =IF(MONTH(DATE('마스터'!$J$3,2,1)+29)=2,DATE('마스터'!$J$3,2,1)+29,"") | AY2: =IF(MONTH(DATE('마스터'!$J$3,2,1)+30)=2,DATE('마스터'!$J$3,2,1)+30,"")
A3: 전체 TO (일자별 부하) | G3: 정원 | H3: =SUM('마스터'!$J$8:$J$10) | U3: =SUM(U$9:U$312) | V3: =SUM(V$9:V$312) | W3: =SUM(W$9:W$312) | X3: =SUM(X$9:X$312) | Y3: =SUM(Y$9:Y$312) | Z3: =SUM(Z$9:Z$312) | AA3: =SUM(AA$9:AA$312) | AB3: =SUM(AB$9:AB$312) | ... AY3: =SUM(AY$9:AY$312)
A4: 영상 TO | G4: 정원 | H4: ='마스터'!$J$8 | U4: =SUMIF($E$9:$E$312,"영상",U$9:U$312) | V4: =SUMIF($E$9:$E$312,"영상",V$9:V$312) | W4: =SUMIF($E$9:$E$312,"영상",W$9:W$312) | X4: =SUMIF($E$9:$E$312,"영상",X$9:X$312) | Y4: =SUMIF($E$9:$E$312,"영상",Y$9:Y$312) | Z4: =SUMIF($E$9:$E$312,"영상",Z$9:Z$312) | AA4: =SUMIF($E$9:$E$312,"영상",AA$9:AA$312) | AB4: =SUMIF($E$9:$E$312,"영상",AB$9:AB$312) | ... AY4: =SUMIF($E$9:$E$312,"영상",AY$9:AY$312)
A5: 이미지 TO | G5: 정원 | H5: ='마스터'!$J$9 | U5: =SUMIF($E$9:$E$312,"이미지",U$9:U$312) | V5: =SUMIF($E$9:$E$312,"이미지",V$9:V$312) | W5: =SUMIF($E$9:$E$312,"이미지",W$9:W$312) | X5: =SUMIF($E$9:$E$312,"이미지",X$9:X$312) | Y5: =SUMIF($E$9:$E$312,"이미지",Y$9:Y$312) | Z5: =SUMIF($E$9:$E$312,"이미지",Z$9:Z$312) | AA5: =SUMIF($E$9:$E$312,"이미지",AA$9:AA$312) | AB5: =SUMIF($E$9:$E$312,"이미지",AB$9:AB$312) | ... AY5: =SUMIF($E$9:$E$312,"이미지",AY$9:AY$312)
A6: 기획 TO | G6: 정원 | H6: ='마스터'!$J$10 | U6: =SUMIF($E$9:$E$312,"기획",U$9:U$312) | V6: =SUMIF($E$9:$E$312,"기획",V$9:V$312) | W6: =SUMIF($E$9:$E$312,"기획",W$9:W$312) | X6: =SUMIF($E$9:$E$312,"기획",X$9:X$312) | Y6: =SUMIF($E$9:$E$312,"기획",Y$9:Y$312) | Z6: =SUMIF($E$9:$E$312,"기획",Z$9:Z$312) | AA6: =SUMIF($E$9:$E$312,"기획",AA$9:AA$312) | AB6: =SUMIF($E$9:$E$312,"기획",AB$9:AB$312) | ... AY6: =SUMIF($E$9:$E$312,"기획",AY$9:AY$312)
A7: ▼ 아래부터 입력. 노란칸=직접 입력 / 회색칸=자동(건드리지 마세요)
A8: 마케팅1팀 (9~68행 · 소재 20개)
A9: =IF($D$9="","",1) | C9: 마케팅1팀 | E9: 기획 | H9: =IF($I$9="","",IF($I$9<0,"🔴지연",IF($I$9<=1,"🟡임박","🟢여유"))) | I9: =IF(OR($G$9="",$K$9=""),"",$G$9-$K$9) | J9: =IF(SUM($L$9:$L$11)=0,"",SUM($L$9:$L$11)) | K9: =IF($J$9="","",MAX($N$9:$N$11)) | L9: =IF(SUM(U9:AY9)=0,"",SUM(U9:AY9)) | M9: =IFERROR(INDEX(U$2:AY$2,MATCH(TRUE,INDEX(U9:AY9<>"",0),0)),"") | N9: =IFERROR(LOOKUP(2,1/(U9:AY9<>""),U$2:AY$2),"")
B10: =IF($B$9="","",$B$9) | C10: 마케팅1팀 | D10: =IF($D$9="","",$D$9) | E10: 이미지 | G10: =IF($G$9="","",$G$9) | L10: =IF(SUM(U10:AY10)=0,"",SUM(U10:AY10)) | M10: =IFERROR(INDEX(U$2:AY$2,MATCH(TRUE,INDEX(U10:AY10<>"",0),0)),"") | N10: =IFERROR(LOOKUP(2,1/(U10:AY10<>""),U$2:AY$2),"")
B11: =IF($B$9="","",$B$9) | C11: 마케팅1팀 | D11: =IF($D$9="","",$D$9) | E11: 영상 | G11: =IF($G$9="","",$G$9) | L11: =IF(SUM(U11:AY11)=0,"",SUM(U11:AY11)) | M11: =IFERROR(INDEX(U$2:AY$2,MATCH(TRUE,INDEX(U11:AY11<>"",0),0)),"") | N11: =IFERROR(LOOKUP(2,1/(U11:AY11<>""),U$2:AY$2),"")
A12: =IF($D$12="","",2) | C12: 마케팅1팀 | E12: 기획 | H12: =IF($I$12="","",IF($I$12<0,"🔴지연",IF($I$12<=1,"🟡임박","🟢여유"))) | I12: =IF(OR($G$12="",$K$12=""),"",$G$12-$K$12) | J12: =IF(SUM($L$12:$L$14)=0,"",SUM($L$12:$L$14)) | K12: =IF($J$12="","",MAX($N$12:$N$14)) | L12: =IF(SUM(U12:AY12)=0,"",SUM(U12:AY12)) | M12: =IFERROR(INDEX(U$2:AY$2,MATCH(TRUE,INDEX(U12:AY12<>"",0),0)),"") | N12: =IFERROR(LOOKUP(2,1/(U12:AY12<>""),U$2:AY$2),"")
B13: =IF($B$12="","",$B$12) | C13: 마케팅1팀 | D13: =IF($D$12="","",$D$12) | E13: 이미지 | G13: =IF($G$12="","",$G$12) | L13: =IF(SUM(U13:AY13)=0,"",SUM(U13:AY13)) | M13: =IFERROR(INDEX(U$2:AY$2,MATCH(TRUE,INDEX(U13:AY13<>"",0),0)),"") | N13: =IFERROR(LOOKUP(2,1/(U13:AY13<>""),U$2:AY$2),"")
B14: =IF($B$12="","",$B$12) | C14: 마케팅1팀 | D14: =IF($D$12="","",$D$12) | E14: 영상 | G14: =IF($G$12="","",$G$12) | L14: =IF(SUM(U14:AY14)=0,"",SUM(U14:AY14)) | M14: =IFERROR(INDEX(U$2:AY$2,MATCH(TRUE,INDEX(U14:AY14<>"",0),0)),"") | N14: =IFERROR(LOOKUP(2,1/(U14:AY14<>""),U$2:AY$2),"")
A15: =IF($D$15="","",3) | C15: 마케팅1팀 | E15: 기획 | H15: =IF($I$15="","",IF($I$15<0,"🔴지연",IF($I$15<=1,"🟡임박","🟢여유"))) | I15: =IF(OR($G$15="",$K$15=""),"",$G$15-$K$15) | J15: =IF(SUM($L$15:$L$17)=0,"",SUM($L$15:$L$17)) | K15: =IF($J$15="","",MAX($N$15:$N$17)) | L15: =IF(SUM(U15:AY15)=0,"",SUM(U15:AY15)) | M15: =IFERROR(INDEX(U$2:AY$2,MATCH(TRUE,INDEX(U15:AY15<>"",0),0)),"") | N15: =IFERROR(LOOKUP(2,1/(U15:AY15<>""),U$2:AY$2),"")
B16: =IF($B$15="","",$B$15) | C16: 마케팅1팀 | D16: =IF($D$15="","",$D$15) | E16: 이미지 | G16: =IF($G$15="","",$G$15) | L16: =IF(SUM(U16:AY16)=0,"",SUM(U16:AY16)) | M16: =IFERROR(INDEX(U$2:AY$2,MATCH(TRUE,INDEX(U16:AY16<>"",0),0)),"") | N16: =IFERROR(LOOKUP(2,1/(U16:AY16<>""),U$2:AY$2),"")
B17: =IF($B$15="","",$B$15) | C17: 마케팅1팀 | D17: =IF($D$15="","",$D$15) | E17: 영상 | G17: =IF($G$15="","",$G$15) | L17: =IF(SUM(U17:AY17)=0,"",SUM(U17:AY17)) | M17: =IFERROR(INDEX(U$2:AY$2,MATCH(TRUE,INDEX(U17:AY17<>"",0),0)),"") | N17: =IFERROR(LOOKUP(2,1/(U17:AY17<>""),U$2:AY$2),"")
A18: =IF($D$18="","",4) | C18: 마케팅1팀 | E18: 기획 | H18: =IF($I$18="","",IF($I$18<0,"🔴지연",IF($I$18<=1,"🟡임박","🟢여유"))) | I18: =IF(OR($G$18="",$K$18=""),"",$G$18-$K$18) | J18: =IF(SUM($L$18:$L$20)=0,"",SUM($L$18:$L$20)) | K18: =IF($J$18="","",MAX($N$18:$N$20)) | L18: =IF(SUM(U18:AY18)=0,"",SUM(U18:AY18)) | M18: =IFERROR(INDEX(U$2:AY$2,MATCH(TRUE,INDEX(U18:AY18<>"",0),0)),"") | N18: =IFERROR(LOOKUP(2,1/(U18:AY18<>""),U$2:AY$2),"")
B19: =IF($B$18="","",$B$18) | C19: 마케팅1팀 | D19: =IF($D$18="","",$D$18) | E19: 이미지 | G19: =IF($G$18="","",$G$18) | L19: =IF(SUM(U19:AY19)=0,"",SUM(U19:AY19)) | M19: =IFERROR(INDEX(U$2:AY$2,MATCH(TRUE,INDEX(U19:AY19<>"",0),0)),"") | N19: =IFERROR(LOOKUP(2,1/(U19:AY19<>""),U$2:AY$2),"")
B20: =IF($B$18="","",$B$18) | C20: 마케팅1팀 | D20: =IF($D$18="","",$D$18) | E20: 영상 | G20: =IF($G$18="","",$G$18) | L20: =IF(SUM(U20:AY20)=0,"",SUM(U20:AY20)) | M20: =IFERROR(INDEX(U$2:AY$2,MATCH(TRUE,INDEX(U20:AY20<>"",0),0)),"") | N20: =IFERROR(LOOKUP(2,1/(U20:AY20<>""),U$2:AY$2),"")
A21: =IF($D$21="","",5) | C21: 마케팅1팀 | E21: 기획 | H21: =IF($I$21="","",IF($I$21<0,"🔴지연",IF($I$21<=1,"🟡임박","🟢여유"))) | I21: =IF(OR($G$21="",$K$21=""),"",$G$21-$K$21) | J21: =IF(SUM($L$21:$L$23)=0,"",SUM($L$21:$L$23)) | K21: =IF($J$21="","",MAX($N$21:$N$23)) | L21: =IF(SUM(U21:AY21)=0,"",SUM(U21:AY21)) | M21: =IFERROR(INDEX(U$2:AY$2,MATCH(TRUE,INDEX(U21:AY21<>"",0),0)),"") | N21: =IFERROR(LOOKUP(2,1/(U21:AY21<>""),U$2:AY$2),"")
B22: =IF($B$21="","",$B$21) | C22: 마케팅1팀 | D22: =IF($D$21="","",$D$21) | E22: 이미지 | G22: =IF($G$21="","",$G$21) | L22: =IF(SUM(U22:AY22)=0,"",SUM(U22:AY22)) | M22: =IFERROR(INDEX(U$2:AY$2,MATCH(TRUE,INDEX(U22:AY22<>"",0),0)),"") | N22: =IFERROR(LOOKUP(2,1/(U22:AY22<>""),U$2:AY$2),"")
B23: =IF($B$21="","",$B$21) | C23: 마케팅1팀 | D23: =IF($D$21="","",$D$21) | E23: 영상 | G23: =IF($G$21="","",$G$21) | L23: =IF(SUM(U23:AY23)=0,"",SUM(U23:AY23)) | M23: =IFERROR(INDEX(U$2:AY$2,MATCH(TRUE,INDEX(U23:AY23<>"",0),0)),"") | N23: =IFERROR(LOOKUP(2,1/(U23:AY23<>""),U$2:AY$2),"")
A24: =IF($D$24="","",6) | C24: 마케팅1팀 | E24: 기획 | H24: =IF($I$24="","",IF($I$24<0,"🔴지연",IF($I$24<=1,"🟡임박","🟢여유"))) | I24: =IF(OR($G$24="",$K$24=""),"",$G$24-$K$24) | J24: =IF(SUM($L$24:$L$26)=0,"",SUM($L$24:$L$26)) | K24: =IF($J$24="","",MAX($N$24:$N$26)) | L24: =IF(SUM(U24:AY24)=0,"",SUM(U24:AY24)) | M24: =IFERROR(INDEX(U$2:AY$2,MATCH(TRUE,INDEX(U24:AY24<>"",0),0)),"") | N24: =IFERROR(LOOKUP(2,1/(U24:AY24<>""),U$2:AY$2),"")
B25: =IF($B$24="","",$B$24) | C25: 마케팅1팀 | D25: =IF($D$24="","",$D$24) | E25: 이미지 | G25: =IF($G$24="","",$G$24) | L25: =IF(SUM(U25:AY25)=0,"",SUM(U25:AY25)) | M25: =IFERROR(INDEX(U$2:AY$2,MATCH(TRUE,INDEX(U25:AY25<>"",0),0)),"") | N25: =IFERROR(LOOKUP(2,1/(U25:AY25<>""),U$2:AY$2),"")
B26: =IF($B$24="","",$B$24) | C26: 마케팅1팀 | D26: =IF($D$24="","",$D$24) | E26: 영상 | G26: =IF($G$24="","",$G$24) | L26: =IF(SUM(U26:AY26)=0,"",SUM(U26:AY26)) | M26: =IFERROR(INDEX(U$2:AY$2,MATCH(TRUE,INDEX(U26:AY26<>"",0),0)),"") | N26: =IFERROR(LOOKUP(2,1/(U26:AY26<>""),U$2:AY$2),"")
A27: =IF($D$27="","",7) | C27: 마케팅1팀 | E27: 기획 | H27: =IF($I$27="","",IF($I$27<0,"🔴지연",IF($I$27<=1,"🟡임박","🟢여유"))) | I27: =IF(OR($G$27="",$K$27=""),"",$G$27-$K$27) | J27: =IF(SUM($L$27:$L$29)=0,"",SUM($L$27:$L$29)) | K27: =IF($J$27="","",MAX($N$27:$N$29)) | L27: =IF(SUM(U27:AY27)=0,"",SUM(U27:AY27)) | M27: =IFERROR(INDEX(U$2:AY$2,MATCH(TRUE,INDEX(U27:AY27<>"",0),0)),"") | N27: =IFERROR(LOOKUP(2,1/(U27:AY27<>""),U$2:AY$2),"")
B28: =IF($B$27="","",$B$27) | C28: 마케팅1팀 | D28: =IF($D$27="","",$D$27) | E28: 이미지 | G28: =IF($G$27="","",$G$27) | L28: =IF(SUM(U28:AY28)=0,"",SUM(U28:AY28)) | M28: =IFERROR(INDEX(U$2:AY$2,MATCH(TRUE,INDEX(U28:AY28<>"",0),0)),"") | N28: =IFERROR(LOOKUP(2,1/(U28:AY28<>""),U$2:AY$2),"")
B29: =IF($B$27="","",$B$27) | C29: 마케팅1팀 | D29: =IF($D$27="","",$D$27) | E29: 영상 | G29: =IF($G$27="","",$G$27) | L29: =IF(SUM(U29:AY29)=0,"",SUM(U29:AY29)) | M29: =IFERROR(INDEX(U$2:AY$2,MATCH(TRUE,INDEX(U29:AY29<>"",0),0)),"") | N29: =IFERROR(LOOKUP(2,1/(U29:AY29<>""),U$2:AY$2),"")
A30: =IF($D$30="","",8) | C30: 마케팅1팀 | E30: 기획 | H30: =IF($I$30="","",IF($I$30<0,"🔴지연",IF($I$30<=1,"🟡임박","🟢여유"))) | I30: =IF(OR($G$30="",$K$30=""),"",$G$30-$K$30) | J30: =IF(SUM($L$30:$L$32)=0,"",SUM($L$30:$L$32)) | K30: =IF($J$30="","",MAX($N$30:$N$32)) | L30: =IF(SUM(U30:AY30)=0,"",SUM(U30:AY30)) | M30: =IFERROR(INDEX(U$2:AY$2,MATCH(TRUE,INDEX(U30:AY30<>"",0),0)),"") | N30: =IFERROR(LOOKUP(2,1/(U30:AY30<>""),U$2:AY$2),"")
B31: =IF($B$30="","",$B$30) | C31: 마케팅1팀 | D31: =IF($D$30="","",$D$30) | E31: 이미지 | G31: =IF($G$30="","",$G$30) | L31: =IF(SUM(U31:AY31)=0,"",SUM(U31:AY31)) | M31: =IFERROR(INDEX(U$2:AY$2,MATCH(TRUE,INDEX(U31:AY31<>"",0),0)),"") | N31: =IFERROR(LOOKUP(2,1/(U31:AY31<>""),U$2:AY$2),"")
B32: =IF($B$30="","",$B$30) | C32: 마케팅1팀 | D32: =IF($D$30="","",$D$30) | E32: 영상 | G32: =IF($G$30="","",$G$30) | L32: =IF(SUM(U32:AY32)=0,"",SUM(U32:AY32)) | M32: =IFERROR(INDEX(U$2:AY$2,MATCH(TRUE,INDEX(U32:AY32<>"",0),0)),"") | N32: =IFERROR(LOOKUP(2,1/(U32:AY32<>""),U$2:AY$2),"")
A33: =IF($D$33="","",9) | C33: 마케팅1팀 | E33: 기획 | H33: =IF($I$33="","",IF($I$33<0,"🔴지연",IF($I$33<=1,"🟡임박","🟢여유"))) | I33: =IF(OR($G$33="",$K$33=""),"",$G$33-$K$33) | J33: =IF(SUM($L$33:$L$35)=0,"",SUM($L$33:$L$35)) | K33: =IF($J$33="","",MAX($N$33:$N$35)) | L33: =IF(SUM(U33:AY33)=0,"",SUM(U33:AY33)) | M33: =IFERROR(INDEX(U$2:AY$2,MATCH(TRUE,INDEX(U33:AY33<>"",0),0)),"") | N33: =IFERROR(LOOKUP(2,1/(U33:AY33<>""),U$2:AY$2),"")
B34: =IF($B$33="","",$B$33) | C34: 마케팅1팀 | D34: =IF($D$33="","",$D$33) | E34: 이미지 | G34: =IF($G$33="","",$G$33) | L34: =IF(SUM(U34:AY34)=0,"",SUM(U34:AY34)) | M34: =IFERROR(INDEX(U$2:AY$2,MATCH(TRUE,INDEX(U34:AY34<>"",0),0)),"") | N34: =IFERROR(LOOKUP(2,1/(U34:AY34<>""),U$2:AY$2),"")
B35: =IF($B$33="","",$B$33) | C35: 마케팅1팀 | D35: =IF($D$33="","",$D$33) | E35: 영상 | G35: =IF($G$33="","",$G$33) | L35: =IF(SUM(U35:AY35)=0,"",SUM(U35:AY35)) | M35: =IFERROR(INDEX(U$2:AY$2,MATCH(TRUE,INDEX(U35:AY35<>"",0),0)),"") | N35: =IFERROR(LOOKUP(2,1/(U35:AY35<>""),U$2:AY$2),"")
A36: =IF($D$36="","",10) | C36: 마케팅1팀 | E36: 기획 | H36: =IF($I$36="","",IF($I$36<0,"🔴지연",IF($I$36<=1,"🟡임박","🟢여유"))) | I36: =IF(OR($G$36="",$K$36=""),"",$G$36-$K$36) | J36: =IF(SUM($L$36:$L$38)=0,"",SUM($L$36:$L$38)) | K36: =IF($J$36="","",MAX($N$36:$N$38)) | L36: =IF(SUM(U36:AY36)=0,"",SUM(U36:AY36)) | M36: =IFERROR(INDEX(U$2:AY$2,MATCH(TRUE,INDEX(U36:AY36<>"",0),0)),"") | N36: =IFERROR(LOOKUP(2,1/(U36:AY36<>""),U$2:AY$2),"")
B37: =IF($B$36="","",$B$36) | C37: 마케팅1팀 | D37: =IF($D$36="","",$D$36) | E37: 이미지 | G37: =IF($G$36="","",$G$36) | L37: =IF(SUM(U37:AY37)=0,"",SUM(U37:AY37)) | M37: =IFERROR(INDEX(U$2:AY$2,MATCH(TRUE,INDEX(U37:AY37<>"",0),0)),"") | N37: =IFERROR(LOOKUP(2,1/(U37:AY37<>""),U$2:AY$2),"")
B38: =IF($B$36="","",$B$36) | C38: 마케팅1팀 | D38: =IF($D$36="","",$D$36) | E38: 영상 | G38: =IF($G$36="","",$G$36) | L38: =IF(SUM(U38:AY38)=0,"",SUM(U38:AY38)) | M38: =IFERROR(INDEX(U$2:AY$2,MATCH(TRUE,INDEX(U38:AY38<>"",0),0)),"") | N38: =IFERROR(LOOKUP(2,1/(U38:AY38<>""),U$2:AY$2),"")
A39: =IF($D$39="","",11) | C39: 마케팅1팀 | E39: 기획 | H39: =IF($I$39="","",IF($I$39<0,"🔴지연",IF($I$39<=1,"🟡임박","🟢여유"))) | I39: =IF(OR($G$39="",$K$39=""),"",$G$39-$K$39) | J39: =IF(SUM($L$39:$L$41)=0,"",SUM($L$39:$L$41)) | K39: =IF($J$39="","",MAX($N$39:$N$41)) | L39: =IF(SUM(U39:AY39)=0,"",SUM(U39:AY39)) | M39: =IFERROR(INDEX(U$2:AY$2,MATCH(TRUE,INDEX(U39:AY39<>"",0),0)),"") | N39: =IFERROR(LOOKUP(2,1/(U39:AY39<>""),U$2:AY$2),"")
B40: =IF($B$39="","",$B$39) | C40: 마케팅1팀 | D40: =IF($D$39="","",$D$39) | E40: 이미지 | G40: =IF($G$39="","",$G$39) | L40: =IF(SUM(U40:AY40)=0,"",SUM(U40:AY40)) | M40: =IFERROR(INDEX(U$2:AY$2,MATCH(TRUE,INDEX(U40:AY40<>"",0),0)),"") | N40: =IFERROR(LOOKUP(2,1/(U40:AY40<>""),U$2:AY$2),"")
...

Sheet 3월
A1: 3월 소재 정보 (소재 1개 = 기획/이미지/영상 3줄) | G1: 고객사 전달일 기준 (자동) | L1: 직군별 집계 (자동) | O1: 수량 (소재당 1번) | R1: 관리 | U1: 3월 간트 - 날짜 칸에 실제 MD 직접 입력 | 상단 4줄 = 일자별 직군 TO 상태
A2: No | B2: 게임 타이틀 | C2: 고객팀 | D2: 소재명(업무명) | E2: 직군 | F2: 담당자 | G2: 고객사 전달일 | H2: 신호 | I2: 전달일 여유 | J2: 소재 총MD | K2: 소재 최종완료 | L2: 직군 MD | M2: 직군 시작일 | N2: 직군 완료일 | O2: 영상 수 | P2: 사이즈 베리 | Q2: 다국어 베리 | R2: 상태 | S2: 비고 | U2: =IF(MONTH(DATE('마스터'!$J$3,3,1)+0)=3,DATE('마스터'!$J$3,3,1)+0,"") | V2: =IF(MONTH(DATE('마스터'!$J$3,3,1)+1)=3,DATE('마스터'!$J$3,3,1)+1,"") | W2: =IF(MONTH(DATE('마스터'!$J$3,3,1)+2)=3,DATE('마스터'!$J$3,3,1)+2,"") | X2: =IF(MONTH(DATE('마스터'!$J$3,3,1)+3)=3,DATE('마스터'!$J$3,3,1)+3,"") | Y2: =IF(MONTH(DATE('마스터'!$J$3,3,1)+4)=3,DATE('마스터'!$J$3,3,1)+4,"") | Z2: =IF(MONTH(DATE('마스터'!$J$3,3,1)+5)=3,DATE('마스터'!$J$3,3,1)+5,"") | AA2: =IF(MONTH(DATE('마스터'!$J$3,3,1)+6)=3,DATE('마스터'!$J$3,3,1)+6,"") | AB2: =IF(MONTH(DATE('마스터'!$J$3,3,1)+7)=3,DATE('마스터'!$J$3,3,1)+7,"") | AC2: =IF(MONTH(DATE('마스터'!$J$3,3,1)+8)=3,DATE('마스터'!$J$3,3,1)+8,"") | AD2: =IF(MONTH(DATE('마스터'!$J$3,3,1)+9)=3,DATE('마스터'!$J$3,3,1)+9,"") | AE2: =IF(MONTH(DATE('마스터'!$J$3,3,1)+10)=3,DATE('마스터'!$J$3,3,1)+10,"") | AF2: =IF(MONTH(DATE('마스터'!$J$3,3,1)+11)=3,DATE('마스터'!$J$3,3,1)+11,"") | AG2: =IF(MONTH(DATE('마스터'!$J$3,3,1)+12)=3,DATE('마스터'!$J$3,3,1)+12,"") | AH2: =IF(MONTH(DATE('마스터'!$J$3,3,1)+13)=3,DATE('마스터'!$J$3,3,1)+13,"") | AI2: =IF(MONTH(DATE('마스터'!$J$3,3,1)+14)=3,DATE('마스터'!$J$3,3,1)+14,"") | AJ2: =IF(MONTH(DATE('마스터'!$J$3,3,1)+15)=3,DATE('마스터'!$J$3,3,1)+15,"") | AK2: =IF(MONTH(DATE('마스터'!$J$3,3,1)+16)=3,DATE('마스터'!$J$3,3,1)+16,"") | AL2: =IF(MONTH(DATE('마스터'!$J$3,3,1)+17)=3,DATE('마스터'!$J$3,3,1)+17,"") | AM2: =IF(MONTH(DATE('마스터'!$J$3,3,1)+18)=3,DATE('마스터'!$J$3,3,1)+18,"") | AN2: =IF(MONTH(DATE('마스터'!$J$3,3,1)+19)=3,DATE('마스터'!$J$3,3,1)+19,"") | AO2: =IF(MONTH(DATE('마스터'!$J$3,3,1)+20)=3,DATE('마스터'!$J$3,3,1)+20,"") | AP2: =IF(MONTH(DATE('마스터'!$J$3,3,1)+21)=3,DATE('마스터'!$J$3,3,1)+21,"") | AQ2: =IF(MONTH(DATE('마스터'!$J$3,3,1)+22)=3,DATE('마스터'!$J$3,3,1)+22,"") | AR2: =IF(MONTH(DATE('마스터'!$J$3,3,1)+23)=3,DATE('마스터'!$J$3,3,1)+23,"") | AS2: =IF(MONTH(DATE('마스터'!$J$3,3,1)+24)=3,DATE('마스터'!$J$3,3,1)+24,"") | AT2: =IF(MONTH(DATE('마스터'!$J$3,3,1)+25)=3,DATE('마스터'!$J$3,3,1)+25,"") | AU2: =IF(MONTH(DATE('마스터'!$J$3,3,1)+26)=3,DATE('마스터'!$J$3,3,1)+26,"") | AV2: =IF(MONTH(DATE('마스터'!$J$3,3,1)+27)=3,DATE('마스터'!$J$3,3,1)+27,"") | AW2: =IF(MONTH(DATE('마스터'!$J$3,3,1)+28)=3,DATE('마스터'!$J$3,3,1)+28,"") | AX2: =IF(MONTH(DATE('마스터'!$J$3,3,1)+29)=3,DATE('마스터'!$J$3,3,1)+29,"") | AY2: =IF(MONTH(DATE('마스터'!$J$3,3,1)+30)=3,DATE('마스터'!$J$3,3,1)+30,"")
A3: 전체 TO (일자별 부하) | G3: 정원 | H3: =SUM('마스터'!$J$8:$J$10) | U3: =SUM(U$9:U$312) | V3: =SUM(V$9:V$312) | W3: =SUM(W$9:W$312) | X3: =SUM(X$9:X$312) | Y3: =SUM(Y$9:Y$312) | Z3: =SUM(Z$9:Z$312) | AA3: =SUM(AA$9:AA$312) | AB3: =SUM(AB$9:AB$312) | ... AY3: =SUM(AY$9:AY$312)
A4: 영상 TO | G4: 정원 | H4: ='마스터'!$J$8 | U4: =SUMIF($E$9:$E$312,"영상",U$9:U$312) | V4: =SUMIF($E$9:$E$312,"영상",V$9:V$312) | W4: =SUMIF($E$9:$E$312,"영상",W$9:W$312) | X4: =SUMIF($E$9:$E$312,"영상",X$9:X$312) | Y4: =SUMIF($E$9:$E$312,"영상",Y$9:Y$312) | Z4: =SUMIF($E$9:$E$312,"영상",Z$9:Z$312) | AA4: =SUMIF($E$9:$E$312,"영상",AA$9:AA$312) | AB4: =SUMIF($E$9:$E$312,"영상",AB$9:AB$312) | ... AY4: =SUMIF($E$9:$E$312,"영상",AY$9:AY$312)
A5: 이미지 TO | G5: 정원 | H5: ='마스터'!$J$9 | U5: =SUMIF($E$9:$E$312,"이미지",U$9:U$312) | V5: =SUMIF($E$9:$E$312,"이미지",V$9:V$312) | W5: =SUMIF($E$9:$E$312,"이미지",W$9:W$312) | X5: =SUMIF($E$9:$E$312,"이미지",X$9:X$312) | Y5: =SUMIF($E$9:$E$312,"이미지",Y$9:Y$312) | Z5: =SUMIF($E$9:$E$312,"이미지",Z$9:Z$312) | AA5: =SUMIF($E$9:$E$312,"이미지",AA$9:AA$312) | AB5: =SUMIF($E$9:$E$312,"이미지",AB$9:AB$312) | ... AY5: =SUMIF($E$9:$E$312,"이미지",AY$9:AY$312)
A6: 기획 TO | G6: 정원 | H6: ='마스터'!$J$10 | U6: =SUMIF($E$9:$E$312,"기획",U$9:U$312) | V6: =SUMIF($E$9:$E$312,"기획",V$9:V$312) | W6: =SUMIF($E$9:$E$312,"기획",W$9:W$312) | X6: =SUMIF($E$9:$E$312,"기획",X$9:X$312) | Y6: =SUMIF($E$9:$E$312,"기획",Y$9:Y$312) | Z6: =SUMIF($E$9:$E$312,"기획",Z$9:Z$312) | AA6: =SUMIF($E$9:$E$312,"기획",AA$9:AA$312) | AB6: =SUMIF($E$9:$E$312,"기획",AB$9:AB$312) | ... AY6: =SUMIF($E$9:$E$312,"기획",AY$9:AY$312)
A7: ▼ 아래부터 입력. 노란칸=직접 입력 / 회색칸=자동(건드리지 마세요)
A8: 마케팅1팀 (9~68행 · 소재 20개)
A9: =IF($D$9="","",1) | C9: 마케팅1팀 | E9: 기획 | H9: =IF($I$9="","",IF($I$9<0,"🔴지연",IF($I$9<=1,"🟡임박","🟢여유"))) | I9: =IF(OR($G$9="",$K$9=""),"",$G$9-$K$9) | J9: =IF(SUM($L$9:$L$11)=0,"",SUM($L$9:$L$11)) | K9: =IF($J$9="","",MAX($N$9:$N$11)) | L9: =IF(SUM(U9:AY9)=0,"",SUM(U9:AY9)) | M9: =IFERROR(INDEX(U$2:AY$2,MATCH(TRUE,INDEX(U9:AY9<>"",0),0)),"") | N9: =IFERROR(LOOKUP(2,1/(U9:AY9<>""),U$2:AY$2),"")
B10: =IF($B$9="","",$B$9) | C10: 마케팅1팀 | D10: =IF($D$9="","",$D$9) | E10: 이미지 | G10: =IF($G$9="","",$G$9) | L10: =IF(SUM(U10:AY10)=0,"",SUM(U10:AY10)) | M10: =IFERROR(INDEX(U$2:AY$2,MATCH(TRUE,INDEX(U10:AY10<>"",0),0)),"") | N10: =IFERROR(LOOKUP(2,1/(U10:AY10<>""),U$2:AY$2),"")
B11: =IF($B$9="","",$B$9) | C11: 마케팅1팀 | D11: =IF($D$9="","",$D$9) | E11: 영상 | G11: =IF($G$9="","",$G$9) | L11: =IF(SUM(U11:AY11)=0,"",SUM(U11:AY11)) | M11: =IFERROR(INDEX(U$2:AY$2,MATCH(TRUE,INDEX(U11:AY11<>"",0),0)),"") | N11: =IFERROR(LOOKUP(2,1/(U11:AY11<>""),U$2:AY$2),"")
A12: =IF($D$12="","",2) | C12: 마케팅1팀 | E12: 기획 | H12: =IF($I$12="","",IF($I$12<0,"🔴지연",IF($I$12<=1,"🟡임박","🟢여유"))) | I12: =IF(OR($G$12="",$K$12=""),"",$G$12-$K$12) | J12: =IF(SUM($L$12:$L$14)=0,"",SUM($L$12:$L$14)) | K12: =IF($J$12="","",MAX($N$12:$N$14)) | L12: =IF(SUM(U12:AY12)=0,"",SUM(U12:AY12)) | M12: =IFERROR(INDEX(U$2:AY$2,MATCH(TRUE,INDEX(U12:AY12<>"",0),0)),"") | N12: =IFERROR(LOOKUP(2,1/(U12:AY12<>""),U$2:AY$2),"")
B13: =IF($B$12="","",$B$12) | C13: 마케팅1팀 | D13: =IF($D$12="","",$D$12) | E13: 이미지 | G13: =IF($G$12="","",$G$12) | L13: =IF(SUM(U13:AY13)=0,"",SUM(U13:AY13)) | M13: =IFERROR(INDEX(U$2:AY$2,MATCH(TRUE,INDEX(U13:AY13<>"",0),0)),"") | N13: =IFERROR(LOOKUP(2,1/(U13:AY13<>""),U$2:AY$2),"")
B14: =IF($B$12="","",$B$12) | C14: 마케팅1팀 | D14: =IF($D$12="","",$D$12) | E14: 영상 | G14: =IF($G$12="","",$G$12) | L14: =IF(SUM(U14:AY14)=0,"",SUM(U14:AY14)) | M14: =IFERROR(INDEX(U$2:AY$2,MATCH(TRUE,INDEX(U14:AY14<>"",0),0)),"") | N14: =IFERROR(LOOKUP(2,1/(U14:AY14<>""),U$2:AY$2),"")
A15: =IF($D$15="","",3) | C15: 마케팅1팀 | E15: 기획 | H15: =IF($I$15="","",IF($I$15<0,"🔴지연",IF($I$15<=1,"🟡임박","🟢여유"))) | I15: =IF(OR($G$15="",$K$15=""),"",$G$15-$K$15) | J15: =IF(SUM($L$15:$L$17)=0,"",SUM($L$15:$L$17)) | K15: =IF($J$15="","",MAX($N$15:$N$17)) | L15: =IF(SUM(U15:AY15)=0,"",SUM(U15:AY15)) | M15: =IFERROR(INDEX(U$2:AY$2,MATCH(TRUE,INDEX(U15:AY15<>"",0),0)),"") | N15: =IFERROR(LOOKUP(2,1/(U15:AY15<>""),U$2:AY$2),"")
B16: =IF($B$15="","",$B$15) | C16: 마케팅1팀 | D16: =IF($D$15="","",$D$15) | E16: 이미지 | G16: =IF($G$15="","",$G$15) | L16: =IF(SUM(U16:AY16)=0,"",SUM(U16:AY16)) | M16: =IFERROR(INDEX(U$2:AY$2,MATCH(TRUE,INDEX(U16:AY16<>"",0),0)),"") | N16: =IFERROR(LOOKUP(2,1/(U16:AY16<>""),U$2:AY$2),"")
B17: =IF($B$15="","",$B$15) | C17: 마케팅1팀 | D17: =IF($D$15="","",$D$15) | E17: 영상 | G17: =IF($G$15="","",$G$15) | L17: =IF(SUM(U17:AY17)=0,"",SUM(U17:AY17)) | M17: =IFERROR(INDEX(U$2:AY$2,MATCH(TRUE,INDEX(U17:AY17<>"",0),0)),"") | N17: =IFERROR(LOOKUP(2,1/(U17:AY17<>""),U$2:AY$2),"")
A18: =IF($D$18="","",4) | C18: 마케팅1팀 | E18: 기획 | H18: =IF($I$18="","",IF($I$18<0,"🔴지연",IF($I$18<=1,"🟡임박","🟢여유"))) | I18: =IF(OR($G$18="",$K$18=""),"",$G$18-$K$18) | J18: =IF(SUM($L$18:$L$20)=0,"",SUM($L$18:$L$20)) | K18: =IF($J$18="","",MAX($N$18:$N$20)) | L18: =IF(SUM(U18:AY18)=0,"",SUM(U18:AY18)) | M18: =IFERROR(INDEX(U$2:AY$2,MATCH(TRUE,INDEX(U18:AY18<>"",0),0)),"") | N18: =IFERROR(LOOKUP(2,1/(U18:AY18<>""),U$2:AY$2),"")
B19: =IF($B$18="","",$B$18) | C19: 마케팅1팀 | D19: =IF($D$18="","",$D$18) | E19: 이미지 | G19: =IF($G$18="","",$G$18) | L19: =IF(SUM(U19:AY19)=0,"",SUM(U19:AY19)) | M19: =IFERROR(INDEX(U$2:AY$2,MATCH(TRUE,INDEX(U19:AY19<>"",0),0)),"") | N19: =IFERROR(LOOKUP(2,1/(U19:AY19<>""),U$2:AY$2),"")
B20: =IF($B$18="","",$B$18) | C20: 마케팅1팀 | D20: =IF($D$18="","",$D$18) | E20: 영상 | G20: =IF($G$18="","",$G$18) | L20: =IF(SUM(U20:AY20)=0,"",SUM(U20:AY20)) | M20: =IFERROR(INDEX(U$2:AY$2,MATCH(TRUE,INDEX(U20:AY20<>"",0),0)),"") | N20: =IFERROR(LOOKUP(2,1/(U20:AY20<>""),U$2:AY$2),"")
A21: =IF($D$21="","",5) | C21: 마케팅1팀 | E21: 기획 | H21: =IF($I$21="","",IF($I$21<0,"🔴지연",IF($I$21<=1,"🟡임박","🟢여유"))) | I21: =IF(OR($G$21="",$K$21=""),"",$G$21-$K$21) | J21: =IF(SUM($L$21:$L$23)=0,"",SUM($L$21:$L$23)) | K21: =IF($J$21="","",MAX($N$21:$N$23)) | L21: =IF(SUM(U21:AY21)=0,"",SUM(U21:AY21)) | M21: =IFERROR(INDEX(U$2:AY$2,MATCH(TRUE,INDEX(U21:AY21<>"",0),0)),"") | N21: =IFERROR(LOOKUP(2,1/(U21:AY21<>""),U$2:AY$2),"")
B22: =IF($B$21="","",$B$21) | C22: 마케팅1팀 | D22: =IF($D$21="","",$D$21) | E22: 이미지 | G22: =IF($G$21="","",$G$21) | L22: =IF(SUM(U22:AY22)=0,"",SUM(U22:AY22)) | M22: =IFERROR(INDEX(U$2:AY$2,MATCH(TRUE,INDEX(U22:AY22<>"",0),0)),"") | N22: =IFERROR(LOOKUP(2,1/(U22:AY22<>""),U$2:AY$2),"")
B23: =IF($B$21="","",$B$21) | C23: 마케팅1팀 | D23: =IF($D$21="","",$D$21) | E23: 영상 | G23: =IF($G$21="","",$G$21) | L23: =IF(SUM(U23:AY23)=0,"",SUM(U23:AY23)) | M23: =IFERROR(INDEX(U$2:AY$2,MATCH(TRUE,INDEX(U23:AY23<>"",0),0)),"") | N23: =IFERROR(LOOKUP(2,1/(U23:AY23<>""),U$2:AY$2),"")
A24: =IF($D$24="","",6) | C24: 마케팅1팀 | E24: 기획 | H24: =IF($I$24="","",IF($I$24<0,"🔴지연",IF($I$24<=1,"🟡임박","🟢여유"))) | I24: =IF(OR($G$24="",$K$24=""),"",$G$24-$K$24) | J24: =IF(SUM($L$24:$L$26)=0,"",SUM($L$24:$L$26)) | K24: =IF($J$24="","",MAX($N$24:$N$26)) | L24: =IF(SUM(U24:AY24)=0,"",SUM(U24:AY24)) | M24: =IFERROR(INDEX(U$2:AY$2,MATCH(TRUE,INDEX(U24:AY24<>"",0),0)),"") | N24: =IFERROR(LOOKUP(2,1/(U24:AY24<>""),U$2:AY$2),"")
B25: =IF($B$24="","",$B$24) | C25: 마케팅1팀 | D25: =IF($D$24="","",$D$24) | E25: 이미지 | G25: =IF($G$24="","",$G$24) | L25: =IF(SUM(U25:AY25)=0,"",SUM(U25:AY25)) | M25: =IFERROR(INDEX(U$2:AY$2,MATCH(TRUE,INDEX(U25:AY25<>"",0),0)),"") | N25: =IFERROR(LOOKUP(2,1/(U25:AY25<>""),U$2:AY$2),"")
B26: =IF($B$24="","",$B$24) | C26: 마케팅1팀 | D26: =IF($D$24="","",$D$24) | E26: 영상 | G26: =IF($G$24="","",$G$24) | L26: =IF(SUM(U26:AY26)=0,"",SUM(U26:AY26)) | M26: =IFERROR(INDEX(U$2:AY$2,MATCH(TRUE,INDEX(U26:AY26<>"",0),0)),"") | N26: =IFERROR(LOOKUP(2,1/(U26:AY26<>""),U$2:AY$2),"")
A27: =IF($D$27="","",7) | C27: 마케팅1팀 | E27: 기획 | H27: =IF($I$27="","",IF($I$27<0,"🔴지연",IF($I$27<=1,"🟡임박","🟢여유"))) | I27: =IF(OR($G$27="",$K$27=""),"",$G$27-$K$27) | J27: =IF(SUM($L$27:$L$29)=0,"",SUM($L$27:$L$29)) | K27: =IF($J$27="","",MAX($N$27:$N$29)) | L27: =IF(SUM(U27:AY27)=0,"",SUM(U27:AY27)) | M27: =IFERROR(INDEX(U$2:AY$2,MATCH(TRUE,INDEX(U27:AY27<>"",0),0)),"") | N27: =IFERROR(LOOKUP(2,1/(U27:AY27<>""),U$2:AY$2),"")
B28: =IF($B$27="","",$B$27) | C28: 마케팅1팀 | D28: =IF($D$27="","",$D$27) | E28: 이미지 | G28: =IF($G$27="","",$G$27) | L28: =IF(SUM(U28:AY28)=0,"",SUM(U28:AY28)) | M28: =IFERROR(INDEX(U$2:AY$2,MATCH(TRUE,INDEX(U28:AY28<>"",0),0)),"") | N28: =IFERROR(LOOKUP(2,1/(U28:AY28<>""),U$2:AY$2),"")
B29: =IF($B$27="","",$B$27) | C29: 마케팅1팀 | D29: =IF($D$27="","",$D$27) | E29: 영상 | G29: =IF($G$27="","",$G$27) | L29: =IF(SUM(U29:AY29)=0,"",SUM(U29:AY29)) | M29: =IFERROR(INDEX(U$2:AY$2,MATCH(TRUE,INDEX(U29:AY29<>"",0),0)),"") | N29: =IFERROR(LOOKUP(2,1/(U29:AY29<>""),U$2:AY$2),"")
A30: =IF($D$30="","",8) | C30: 마케팅1팀 | E30: 기획 | H30: =IF($I$30="","",IF($I$30<0,"🔴지연",IF($I$30<=1,"🟡임박","🟢여유"))) | I30: =IF(OR($G$30="",$K$30=""),"",$G$30-$K$30) | J30: =IF(SUM($L$30:$L$32)=0,"",SUM($L$30:$L$32)) | K30: =IF($J$30="","",MAX($N$30:$N$32)) | L30: =IF(SUM(U30:AY30)=0,"",SUM(U30:AY30)) | M30: =IFERROR(INDEX(U$2:AY$2,MATCH(TRUE,INDEX(U30:AY30<>"",0),0)),"") | N30: =IFERROR(LOOKUP(2,1/(U30:AY30<>""),U$2:AY$2),"")
B31: =IF($B$30="","",$B$30) | C31: 마케팅1팀 | D31: =IF($D$30="","",$D$30) | E31: 이미지 | G31: =IF($G$30="","",$G$30) | L31: =IF(SUM(U31:AY31)=0,"",SUM(U31:AY31)) | M31: =IFERROR(INDEX(U$2:AY$2,MATCH(TRUE,INDEX(U31:AY31<>"",0),0)),"") | N31: =IFERROR(LOOKUP(2,1/(U31:AY31<>""),U$2:AY$2),"")
B32: =IF($B$30="","",$B$30) | C32: 마케팅1팀 | D32: =IF($D$30="","",$D$30) | E32: 영상 | G32: =IF($G$30="","",$G$30) | L32: =IF(SUM(U32:AY32)=0,"",SUM(U32:AY32)) | M32: =IFERROR(INDEX(U$2:AY$2,MATCH(TRUE,INDEX(U32:AY32<>"",0),0)),"") | N32: =IFERROR(LOOKUP(2,1/(U32:AY32<>""),U$2:AY$2),"")
A33: =IF($D$33="","",9) | C33: 마케팅1팀 | E33: 기획 | H33: =IF($I$33="","",IF($I$33<0,"🔴지연",IF($I$33<=1,"🟡임박","🟢여유"))) | I33: =IF(OR($G$33="",$K$33=""),"",$G$33-$K$33) | J33: =IF(SUM($L$33:$L$35)=0,"",SUM($L$33:$L$35)) | K33: =IF($J$33="","",MAX($N$33:$N$35)) | L33: =IF(SUM(U33:AY33)=0,"",SUM(U33:AY33)) | M33: =IFERROR(INDEX(U$2:AY$2,MATCH(TRUE,INDEX(U33:AY33<>"",0),0)),"") | N33: =IFERROR(LOOKUP(2,1/(U33:AY33<>""),U$2:AY$2),"")
B34: =IF($B$33="","",$B$33) | C34: 마케팅1팀 | D34: =IF($D$33="","",$D$33) | E34: 이미지 | G34: =IF($G$33="","",$G$33) | L34: =IF(SUM(U34:AY34)=0,"",SUM(U34:AY34)) | M34: =IFERROR(INDEX(U$2:AY$2,MATCH(TRUE,INDEX(U34:AY34<>"",0),0)),"") | N34: =IFERROR(LOOKUP(2,1/(U34:AY34<>""),U$2:AY$2),"")
B35: =IF($B$33="","",$B$33) | C35: 마케팅1팀 | D35: =IF($D$33="","",$D$33) | E35: 영상 | G35: =IF($G$33="","",$G$33) | L35: =IF(SUM(U35:AY35)=0,"",SUM(U35:AY35)) | M35: =IFERROR(INDEX(U$2:AY$2,MATCH(TRUE,INDEX(U35:AY35<>"",0),0)),"") | N35: =IFERROR(LOOKUP(2,1/(U35:AY35<>""),U$2:AY$2),"")
A36: =IF($D$36="","",10) | C36: 마케팅1팀 | E36: 기획 | H36: =IF($I$36="","",IF($I$36<0,"🔴지연",IF($I$36<=1,"🟡임박","🟢여유"))) | I36: =IF(OR($G$36="",$K$36=""),"",$G$36-$K$36) | J36: =IF(SUM($L$36:$L$38)=0,"",SUM($L$36:$L$38)) | K36: =IF($J$36="","",MAX($N$36:$N$38)) | L36: =IF(SUM(U36:AY36)=0,"",SUM(U36:AY36)) | M36: =IFERROR(INDEX(U$2:AY$2,MATCH(TRUE,INDEX(U36:AY36<>"",0),0)),"") | N36: =IFERROR(LOOKUP(2,1/(U36:AY36<>""),U$2:AY$2),"")
B37: =IF($B$36="","",$B$36) | C37: 마케팅1팀 | D37: =IF($D$36="","",$D$36) | E37: 이미지 | G37: =IF($G$36="","",$G$36) | L37: =IF(SUM(U37:AY37)=0,"",SUM(U37:AY37)) | M37: =IFERROR(INDEX(U$2:AY$2,MATCH(TRUE,INDEX(U37:AY37<>"",0),0)),"") | N37: =IFERROR(LOOKUP(2,1/(U37:AY37<>""),U$2:AY$2),"")
B38: =IF($B$36="","",$B$36) | C38: 마케팅1팀 | D38: =IF($D$36="","",$D$36) | E38: 영상 | G38: =IF($G$36="","",$G$36) | L38: =IF(SUM(U38:AY38)=0,"",SUM(U38:AY38)) | M38: =IFERROR(INDEX(U$2:AY$2,MATCH(TRUE,INDEX(U38:AY38<>"",0),0)),"") | N38: =IFERROR(LOOKUP(2,1/(U38:AY38<>""),U$2:AY$2),"")
A39: =IF($D$39="","",11) | C39: 마케팅1팀 | E39: 기획 | H39: =IF($I$39="","",IF($I$39<0,"🔴지연",IF($I$39<=1,"🟡임박","🟢여유"))) | I39: =IF(OR($G$39="",$K$39=""),"",$G$39-$K$39) | J39: =IF(SUM($L$39:$L$41)=0,"",SUM($L$39:$L$41)) | K39: =IF($J$39="","",MAX($N$39:$N$41)) | L39: =IF(SUM(U39:AY39)=0,"",SUM(U39:AY39)) | M39: =IFERROR(INDEX(U$2:AY$2,MATCH(TRUE,INDEX(U39:AY39<>"",0),0)),"") | N39: =IFERROR(LOOKUP(2,1/(U39:AY39<>""),U$2:AY$2),"")
B40: =IF($B$39="","",$B$39) | C40: 마케팅1팀 | D40: =IF($D$39="","",$D$39) | E40: 이미지 | G40: =IF($G$39="","",$G$39) | L40: =IF(SUM(U40:AY40)=0,"",SUM(U40:AY40)) | M40: =IFERROR(INDEX(U$2:AY$2,MATCH(TRUE,INDEX(U40:AY40<>"",0),0)),"") | N40: =IFERROR(LOOKUP(2,1/(U40:AY40<>""),U$2:AY$2),"")
...

Sheet 4월
A1: 4월 소재 정보 (소재 1개 = 기획/이미지/영상 3줄) | G1: 고객사 전달일 기준 (자동) | L1: 직군별 집계 (자동) | O1: 수량 (소재당 1번) | R1: 관리 | U1: 4월 간트 - 날짜 칸에 실제 MD 직접 입력 | 상단 4줄 = 일자별 직군 TO 상태
A2: No | B2: 게임 타이틀 | C2: 고객팀 | D2: 소재명(업무명) | E2: 직군 | F2: 담당자 | G2: 고객사 전달일 | H2: 신호 | I2: 전달일 여유 | J2: 소재 총MD | K2: 소재 최종완료 | L2: 직군 MD | M2: 직군 시작일 | N2: 직군 완료일 | O2: 영상 수 | P2: 사이즈 베리 | Q2: 다국어 베리 | R2: 상태 | S2: 비고 | U2: =IF(MONTH(DATE('마스터'!$J$3,4,1)+0)=4,DATE('마스터'!$J$3,4,1)+0,"") | V2: =IF(MONTH(DATE('마스터'!$J$3,4,1)+1)=4,DATE('마스터'!$J$3,4,1)+1,"") | W2: =IF(MONTH(DATE('마스터'!$J$3,4,1)+2)=4,DATE('마스터'!$J$3,4,1)+2,"") | X2: =IF(MONTH(DATE('마스터'!$J$3,4,1)+3)=4,DATE('마스터'!$J$3,4,1)+3,"") | Y2: =IF(MONTH(DATE('마스터'!$J$3,4,1)+4)=4,DATE('마스터'!$J$3,4,1)+4,"") | Z2: =IF(MONTH(DATE('마스터'!$J$3,4,1)+5)=4,DATE('마스터'!$J$3,4,1)+5,"") | AA2: =IF(MONTH(DATE('마스터'!$J$3,4,1)+6)=4,DATE('마스터'!$J$3,4,1)+6,"") | AB2: =IF(MONTH(DATE('마스터'!$J$3,4,1)+7)=4,DATE('마스터'!$J$3,4,1)+7,"") | AC2: =IF(MONTH(DATE('마스터'!$J$3,4,1)+8)=4,DATE('마스터'!$J$3,4,1)+8,"") | AD2: =IF(MONTH(DATE('마스터'!$J$3,4,1)+9)=4,DATE('마스터'!$J$3,4,1)+9,"") | AE2: =IF(MONTH(DATE('마스터'!$J$3,4,1)+10)=4,DATE('마스터'!$J$3,4,1)+10,"") | AF2: =IF(MONTH(DATE('마스터'!$J$3,4,1)+11)=4,DATE('마스터'!$J$3,4,1)+11,"") | AG2: =IF(MONTH(DATE('마스터'!$J$3,4,1)+12)=4,DATE('마스터'!$J$3,4,1)+12,"") | AH2: =IF(MONTH(DATE('마스터'!$J$3,4,1)+13)=4,DATE('마스터'!$J$3,4,1)+13,"") | AI2: =IF(MONTH(DATE('마스터'!$J$3,4,1)+14)=4,DATE('마스터'!$J$3,4,1)+14,"") | AJ2: =IF(MONTH(DATE('마스터'!$J$3,4,1)+15)=4,DATE('마스터'!$J$3,4,1)+15,"") | AK2: =IF(MONTH(DATE('마스터'!$J$3,4,1)+16)=4,DATE('마스터'!$J$3,4,1)+16,"") | AL2: =IF(MONTH(DATE('마스터'!$J$3,4,1)+17)=4,DATE('마스터'!$J$3,4,1)+17,"") | AM2: =IF(MONTH(DATE('마스터'!$J$3,4,1)+18)=4,DATE('마스터'!$J$3,4,1)+18,"") | AN2: =IF(MONTH(DATE('마스터'!$J$3,4,1)+19)=4,DATE('마스터'!$J$3,4,1)+19,"") | AO2: =IF(MONTH(DATE('마스터'!$J$3,4,1)+20)=4,DATE('마스터'!$J$3,4,1)+20,"") | AP2: =IF(MONTH(DATE('마스터'!$J$3,4,1)+21)=4,DATE('마스터'!$J$3,4,1)+21,"") | AQ2: =IF(MONTH(DATE('마스터'!$J$3,4,1)+22)=4,DATE('마스터'!$J$3,4,1)+22,"") | AR2: =IF(MONTH(DATE('마스터'!$J$3,4,1)+23)=4,DATE('마스터'!$J$3,4,1)+23,"") | AS2: =IF(MONTH(DATE('마스터'!$J$3,4,1)+24)=4,DATE('마스터'!$J$3,4,1)+24,"") | AT2: =IF(MONTH(DATE('마스터'!$J$3,4,1)+25)=4,DATE('마스터'!$J$3,4,1)+25,"") | AU2: =IF(MONTH(DATE('마스터'!$J$3,4,1)+26)=4,DATE('마스터'!$J$3,4,1)+26,"") | AV2: =IF(MONTH(DATE('마스터'!$J$3,4,1)+27)=4,DATE('마스터'!$J$3,4,1)+27,"") | AW2: =IF(MONTH(DATE('마스터'!$J$3,4,1)+28)=4,DATE('마스터'!$J$3,4,1)+28,"") | AX2: =IF(MONTH(DATE('마스터'!$J$3,4,1)+29)=4,DATE('마스터'!$J$3,4,1)+29,"") | AY2: =IF(MONTH(DATE('마스터'!$J$3,4,1)+30)=4,DATE('마스터'!$J$3,4,1)+30,"")
A3: 전체 TO (일자별 부하) | G3: 정원 | H3: =SUM('마스터'!$J$8:$J$10) | U3: =SUM(U$9:U$312) | V3: =SUM(V$9:V$312) | W3: =SUM(W$9:W$312) | X3: =SUM(X$9:X$312) | Y3: =SUM(Y$9:Y$312) | Z3: =SUM(Z$9:Z$312) | AA3: =SUM(AA$9:AA$312) | AB3: =SUM(AB$9:AB$312) | ... AY3: =SUM(AY$9:AY$312)
A4: 영상 TO | G4: 정원 | H4: ='마스터'!$J$8 | U4: =SUMIF($E$9:$E$312,"영상",U$9:U$312) | V4: =SUMIF($E$9:$E$312,"영상",V$9:V$312) | W4: =SUMIF($E$9:$E$312,"영상",W$9:W$312) | X4: =SUMIF($E$9:$E$312,"영상",X$9:X$312) | Y4: =SUMIF($E$9:$E$312,"영상",Y$9:Y$312) | Z4: =SUMIF($E$9:$E$312,"영상",Z$9:Z$312) | AA4: =SUMIF($E$9:$E$312,"영상",AA$9:AA$312) | AB4: =SUMIF($E$9:$E$312,"영상",AB$9:AB$312) | ... AY4: =SUMIF($E$9:$E$312,"영상",AY$9:AY$312)
A5: 이미지 TO | G5: 정원 | H5: ='마스터'!$J$9 | U5: =SUMIF($E$9:$E$312,"이미지",U$9:U$312) | V5: =SUMIF($E$9:$E$312,"이미지",V$9:V$312) | W5: =SUMIF($E$9:$E$312,"이미지",W$9:W$312) | X5: =SUMIF($E$9:$E$312,"이미지",X$9:X$312) | Y5: =SUMIF($E$9:$E$312,"이미지",Y$9:Y$312) | Z5: =SUMIF($E$9:$E$312,"이미지",Z$9:Z$312) | AA5: =SUMIF($E$9:$E$312,"이미지",AA$9:AA$312) | AB5: =SUMIF($E$9:$E$312,"이미지",AB$9:AB$312) | ... AY5: =SUMIF($E$9:$E$312,"이미지",AY$9:AY$312)
A6: 기획 TO | G6: 정원 | H6: ='마스터'!$J$10 | U6: =SUMIF($E$9:$E$312,"기획",U$9:U$312) | V6: =SUMIF($E$9:$E$312,"기획",V$9:V$312) | W6: =SUMIF($E$9:$E$312,"기획",W$9:W$312) | X6: =SUMIF($E$9:$E$312,"기획",X$9:X$312) | Y6: =SUMIF($E$9:$E$312,"기획",Y$9:Y$312) | Z6: =SUMIF($E$9:$E$312,"기획",Z$9:Z$312) | AA6: =SUMIF($E$9:$E$312,"기획",AA$9:AA$312) | AB6: =SUMIF($E$9:$E$312,"기획",AB$9:AB$312) | ... AY6: =SUMIF($E$9:$E$312,"기획",AY$9:AY$312)
A7: ▼ 아래부터 입력. 노란칸=직접 입력 / 회색칸=자동(건드리지 마세요)
A8: 마케팅1팀 (9~68행 · 소재 20개)
A9: =IF($D$9="","",1) | C9: 마케팅1팀 | E9: 기획 | H9: =IF($I$9="","",IF($I$9<0,"🔴지연",IF($I$9<=1,"🟡임박","🟢여유"))) | I9: =IF(OR($G$9="",$K$9=""),"",$G$9-$K$9) | J9: =IF(SUM($L$9:$L$11)=0,"",SUM($L$9:$L$11)) | K9: =IF($J$9="","",MAX($N$9:$N$11)) | L9: =IF(SUM(U9:AY9)=0,"",SUM(U9:AY9)) | M9: =IFERROR(INDEX(U$2:AY$2,MATCH(TRUE,INDEX(U9:AY9<>"",0),0)),"") | N9: =IFERROR(LOOKUP(2,1/(U9:AY9<>""),U$2:AY$2),"")
B10: =IF($B$9="","",$B$9) | C10: 마케팅1팀 | D10: =IF($D$9="","",$D$9) | E10: 이미지 | G10: =IF($G$9="","",$G$9) | L10: =IF(SUM(U10:AY10)=0,"",SUM(U10:AY10)) | M10: =IFERROR(INDEX(U$2:AY$2,MATCH(TRUE,INDEX(U10:AY10<>"",0),0)),"") | N10: =IFERROR(LOOKUP(2,1/(U10:AY10<>""),U$2:AY$2),"")
B11: =IF($B$9="","",$B$9) | C11: 마케팅1팀 | D11: =IF($D$9="","",$D$9) | E11: 영상 | G11: =IF($G$9="","",$G$9) | L11: =IF(SUM(U11:AY11)=0,"",SUM(U11:AY11)) | M11: =IFERROR(INDEX(U$2:AY$2,MATCH(TRUE,INDEX(U11:AY11<>"",0),0)),"") | N11: =IFERROR(LOOKUP(2,1/(U11:AY11<>""),U$2:AY$2),"")
A12: =IF($D$12="","",2) | C12: 마케팅1팀 | E12: 기획 | H12: =IF($I$12="","",IF($I$12<0,"🔴지연",IF($I$12<=1,"🟡임박","🟢여유"))) | I12: =IF(OR($G$12="",$K$12=""),"",$G$12-$K$12) | J12: =IF(SUM($L$12:$L$14)=0,"",SUM($L$12:$L$14)) | K12: =IF($J$12="","",MAX($N$12:$N$14)) | L12: =IF(SUM(U12:AY12)=0,"",SUM(U12:AY12)) | M12: =IFERROR(INDEX(U$2:AY$2,MATCH(TRUE,INDEX(U12:AY12<>"",0),0)),"") | N12: =IFERROR(LOOKUP(2,1/(U12:AY12<>""),U$2:AY$2),"")
B13: =IF($B$12="","",$B$12) | C13: 마케팅1팀 | D13: =IF($D$12="","",$D$12) | E13: 이미지 | G13: =IF($G$12="","",$G$12) | L13: =IF(SUM(U13:AY13)=0,"",SUM(U13:AY13)) | M13: =IFERROR(INDEX(U$2:AY$2,MATCH(TRUE,INDEX(U13:AY13<>"",0),0)),"") | N13: =IFERROR(LOOKUP(2,1/(U13:AY13<>""),U$2:AY$2),"")
B14: =IF($B$12="","",$B$12) | C14: 마케팅1팀 | D14: =IF($D$12="","",$D$12) | E14: 영상 | G14: =IF($G$12="","",$G$12) | L14: =IF(SUM(U14:AY14)=0,"",SUM(U14:AY14)) | M14: =IFERROR(INDEX(U$2:AY$2,MATCH(TRUE,INDEX(U14:AY14<>"",0),0)),"") | N14: =IFERROR(LOOKUP(2,1/(U14:AY14<>""),U$2:AY$2),"")
A15: =IF($D$15="","",3) | C15: 마케팅1팀 | E15: 기획 | H15: =IF($I$15="","",IF($I$15<0,"🔴지연",IF($I$15<=1,"🟡임박","🟢여유"))) | I15: =IF(OR($G$15="",$K$15=""),"",$G$15-$K$15) | J15: =IF(SUM($L$15:$L$17)=0,"",SUM($L$15:$L$17)) | K15: =IF($J$15="","",MAX($N$15:$N$17)) | L15: =IF(SUM(U15:AY15)=0,"",SUM(U15:AY15)) | M15: =IFERROR(INDEX(U$2:AY$2,MATCH(TRUE,INDEX(U15:AY15<>"",0),0)),"") | N15: =IFERROR(LOOKUP(2,1/(U15:AY15<>""),U$2:AY$2),"")
B16: =IF($B$15="","",$B$15) | C16: 마케팅1팀 | D16: =IF($D$15="","",$D$15) | E16: 이미지 | G16: =IF($G$15="","",$G$15) | L16: =IF(SUM(U16:AY16)=0,"",SUM(U16:AY16)) | M16: =IFERROR(INDEX(U$2:AY$2,MATCH(TRUE,INDEX(U16:AY16<>"",0),0)),"") | N16: =IFERROR(LOOKUP(2,1/(U16:AY16<>""),U$2:AY$2),"")
B17: =IF($B$15="","",$B$15) | C17: 마케팅1팀 | D17: =IF($D$15="","",$D$15) | E17: 영상 | G17: =IF($G$15="","",$G$15) | L17: =IF(SUM(U17:AY17)=0,"",SUM(U17:AY17)) | M17: =IFERROR(INDEX(U$2:AY$2,MATCH(TRUE,INDEX(U17:AY17<>"",0),0)),"") | N17: =IFERROR(LOOKUP(2,1/(U17:AY17<>""),U$2:AY$2),"")
